#VRML_SIM V7.4.3 utf8
WorldInfo {
  info [
    "Aldebaran's Nao H25 V4.0"
    "Author: Yvan Bourquin - www.cyberbotics.com"
    "Date: 06 Feb 2012"
  ]
  title "Aldebaran Nao H25 V4.0"
  CFM 2.11e-06
  ERP 0.29
  basicTimeStep 20
  contactProperties [
    ContactProperties {
      material1 "Nao foot material"
      coulombFriction 8.24
      bounce 0.9
      bounceVelocity 0.003
    }
  ]
}
Viewpoint {
  orientation 0.65697 -0.702989 -0.272392 5.26081
  position 6.16307 4.5548 2.42251
}
Background {
  skyColor [
    0.66 0.66 1
  ]
}
DirectionalLight {
  ambientIntensity 1
  direction 0.4 -0.7 -0.3
  intensity 0.6
  castShadows TRUE
}
PointLight {
  intensity 0
  location 0 1.6 0
}
DEF ROBOT_DOOR Robot {
  translation 2.86 1.03 0.32
  children [
    DEF STATIC_BODY Shape {
      appearance Appearance {
        material Material {
          diffuseColor 0.317647 0.317647 0.317647
        }
      }
      geometry Box {
        size 0.05 2.05 0.3
      }
    }
    DEF DOOR HingeJoint {
      jointParameters HingeJointParameters {
        axis 0 1 0
        anchor 0.05 0 0
        minStop -1.5708
        maxStop 1.5708
        staticFriction 1.4
      }
      device PositionSensor {
      }
      endPoint Solid {
        translation 0.425 0 0
        children [
          Shape {
            appearance Appearance {
              texture ImageTexture {
                url [
                  "C:/Users/Nathaniel/sim_project_NAO/trunk/textures/single_door_common.png"
                ]
              }
            }
            geometry DEF DOOR_SHAPE Box {
              size 0.8 2 0.05
            }
          }
        ]
        boundingObject USE DOOR_SHAPE
        physics Physics {
          density -1
          mass 10
        }
      }
    }
  ]
  boundingObject USE STATIC_BODY
}
Floor {
  size 25 25
  tileSize 0.8 0.8
  texture [
    "textures/checkered_marble.png"
  ]
}
DEF ORIGIN WallGap {
  translation 1.72142 7.86698e-16 -0.858051
}
DEF NAO_1 Nao {
  translation 3.23 0.334006 0.66
  rotation 0.577351 -0.577351 -0.57735 4.18879
}
SphericalSkyDome {
}
