#VRML_SIM V7.4.3 utf8
WorldInfo {
  info [
    "Aldebaran's Nao H25 V4.0"
    "Author: Yvan Bourquin - www.cyberbotics.com"
    "Date: 06 Feb 2012"
  ]
  title "Aldebaran Nao H25 V4.0"
  CFM 2.11e-06
  ERP 0.29
  basicTimeStep 20
  contactProperties [
    ContactProperties {
      material1 "Nao foot material"
      coulombFriction 8.24
      bounce 0.9
      bounceVelocity 0.003
    }
  ]
}
Viewpoint {
  orientation -0.44616 0.8735 0.194777 0.864594
  position 9.08327 4.97454 5.29222
}
Background {
  skyColor [
    0.66 0.66 1
  ]
}
DirectionalLight {
  ambientIntensity 1
  direction 0.4 -0.7 -0.3
  intensity 0.6
  castShadows TRUE
}
PointLight {
  intensity 0
  location 0 1.6 0
}
DEF ROBOT_DOOR Robot {
  translation 2.86 1.03 0.32
  children [
    DEF STATIC_BODY Shape {
      geometry Box {
        size 0.05 2.05 0.3
      }
    }
    DEF DOOR HingeJoint {
      endPoint Solid {
        translation 0.45 0 0
        children [
          Shape {
            geometry Box {
              size 0.8 2 0.05
            }
          }
        ]
      }
    }
  ]
}
SingleDoorCommon {
  translation 3.28 0 -0.18
}
Robot {
  translation 1.41716 1.03 0.307061
  children [
    HingeJoint {
    }
    DEF DOOR Shape {
      geometry Box {
        size 0.9 2.05 0.3
      }
    }
  ]
}
Floor {
  size 25 25
  tileSize 0.8 0.8
  texture [
    "textures/checkered_marble.png"
  ]
}
DEF ORIGIN WallGap {
  translation 1.72142 7.86698e-16 -0.858051
}
DEF NAO_1 Nao {
  translation 3.23 0.334007 1.46
  rotation 0.577351 0.577351 0.577349 4.18879
}
SphericalSkyDome {
}
