#VRML_SIM V7.4.3 utf8
WorldInfo {
  info [
    "Aldebaran's Nao H25 V4.0"
    "Author: Yvan Bourquin - www.cyberbotics.com"
    "Date: 06 Feb 2012"
  ]
  title "Aldebaran Nao H25 V4.0"
  CFM 2.11e-06
  ERP 0.29
  basicTimeStep 20
  contactProperties [
    ContactProperties {
      material1 "Nao foot material"
      coulombFriction 8.24
      bounce 0.9
      bounceVelocity 0.003
    }
  ]
}
Viewpoint {
  orientation 0.627621 -0.596662 -0.500086 4.45005
  position 5.03113 8.29163 2.47573
}
Background {
  skyColor [
    0.66 0.66 1
  ]
}
DirectionalLight {
  ambientIntensity 1
  direction 0.4 -0.7 -0.3
  castShadows TRUE
}
PointLight {
  intensity 0
  location 0 1.6 0
}
DEF ROBOT_DOOR Robot {
  translation 4.12176 1.03 1.65064
  children [
    DEF STATIC_BODY Shape {
      appearance Appearance {
        material Material {
          diffuseColor 0.317647 0.317647 0.317647
        }
      }
      geometry Box {
        size 0.05 2.05 0.3
      }
    }
    DEF DOOR HingeJoint {
      jointParameters HingeJointParameters {
        axis 0 1 0
        anchor 0.05 0 0
        minStop -1.5708
        maxStop 1.5708
        staticFriction 1
      }
      device PositionSensor {
      }
      endPoint Solid {
        translation 0.425 0 0
        children [
          DEF H2 Solid {
            translation 0 -0.51 0
            children [
              Shape {
                appearance Appearance {
                  material Material {
                    ambientIntensity 1
                    diffuseColor 1 1 1
                    emissiveColor 1 1 1
                    shininess 0
                    specularColor 1 1 1
                  }
                  texture ImageTexture {
                    url [
                      "textures/hall2.png"
                    ]
                  }
                }
                geometry Box {
                  size 0.5 0.5 0.08
                }
              }
            ]
          }
          Shape {
            appearance Appearance {
              texture ImageTexture {
                url [
                  "textures/single_door_common.png"
                ]
              }
            }
            geometry DEF DOOR_SHAPE Box {
              size 0.8 2 0.05
            }
          }
        ]
        boundingObject USE DOOR_SHAPE
        physics Physics {
          density -1
          mass 10
        }
      }
    }
  ]
  boundingObject USE STATIC_BODY
}
Floor {
  size 25 25
  tileSize 0.8 0.8
  texture [
    "textures/checkered_marble.png"
  ]
}
Wall {
  translation 2.55 0 3.42
}
Wall {
  translation 2.55 0 2.18
}
Wall {
  translation 3.92 0 0.5
  rotation 0 1 0 1.5708
}
Wall {
  translation 5.16 0 0.5
  rotation 0 1 0 1.5708
}
Wall {
  translation 6.5 0 3.42
}
Wall {
  translation 6.5 0 2.18
}
DEF H1 Solid {
  translation 3.56751 0.58 2.75623
  rotation 0 1 0 4.7124
  children [
    Shape {
      appearance Appearance {
        material Material {
          ambientIntensity 1
          diffuseColor 1 1 1
          emissiveColor 1 1 1
          shininess 0
          specularColor 1 1 1
        }
        texture ImageTexture {
          url [
            "textures/hall1.png"
          ]
        }
      }
      geometry Box {
        size 0.5 0.5 0.01
      }
    }
  ]
}
DEF H3 Solid {
  translation 5.58751 0.58 2.75621
  rotation 0 1 0 4.7124
  children [
    Shape {
      appearance Appearance {
        material Material {
          ambientIntensity 1
          diffuseColor 1 1 1
          emissiveColor 1 1 1
          shininess 0
          specularColor 1 1 1
        }
        texture ImageTexture {
          url [
            "textures/hall3.png"
          ]
        }
      }
      geometry Box {
        size 0.5 0.5 0.01
      }
    }
  ]
}
DEF NAO_1 Nao {
  translation 4.54 0.344004 2.85
  rotation -0.57735 0.57735 0.57735 2.0944
  cameraWidth 640
  cameraHeight 480
  cameraPixelSize 0.5
}
SphericalSkyDome {
}
