#VRML_SIM V7.4.3 utf8
WorldInfo {
  info [
    "Aldebaran's Nao H25 V4.0"
    "Author: Yvan Bourquin - www.cyberbotics.com"
    "Date: 06 Feb 2012"
  ]
  title "Aldebaran Nao H25 V4.0"
  CFM 2.11e-06
  ERP 0.29
  basicTimeStep 20
  contactProperties [
    ContactProperties {
      material1 "Nao foot material"
      coulombFriction 8.24
      bounce 0.9
      bounceVelocity 0.003
    }
  ]
}
Viewpoint {
  orientation -0.245015 0.936648 0.250315 1.61107
  position 9.67152 3.24195 3.92542
}
Background {
  skyColor [
    0.66 0.66 1
  ]
}
DirectionalLight {
  ambientIntensity 1
  direction 0.4 -0.7 -0.3
  castShadows TRUE
}
PointLight {
  intensity 0
  location 0 1.6 0
}
DEF ROBOT_DOOR Robot {
  translation 5.28176 1.03 1.55064
  children [
    DEF STATIC_BODY Shape {
      appearance Appearance {
        material Material {
          diffuseColor 0.317647 0.317647 0.317647
        }
      }
      geometry Box {
        size 0.05 2.05 0.3
      }
    }
    DEF DOOR HingeJoint {
      jointParameters HingeJointParameters {
        axis 0 1 0
        anchor 0.05 0 0
        minStop -1.5708
        maxStop 1.5708
        staticFriction 1
      }
      device PositionSensor {
      }
      endPoint Solid {
        translation 0.425 0 0
        children [
          Shape {
            appearance Appearance {
              texture ImageTexture {
                url [
                  "textures/single_door_common.png"
                ]
              }
            }
            geometry DEF DOOR_SHAPE Box {
              size 0.8 2 0.05
            }
          }
        ]
        boundingObject USE DOOR_SHAPE
        physics Physics {
          density -1
          mass 10
        }
      }
    }
  ]
  boundingObject USE STATIC_BODY
}
Floor {
  size 25 25
  tileSize 0.8 0.8
  texture [
    "textures/checkered_marble.png"
  ]
}
Wall {
  translation 4.54 -1.24 3.05
  rotation 0 1 0 1.5708
}
Wall {
  translation 6.86 -1.24 3.04999
  rotation 0 1 0 1.5708
}
DEF H1S2E Solid {
  translation 4.68752 0.51 2.27622
  rotation 0 1 0 1.5708
  children [
    Shape {
      appearance Appearance {
        material Material {
          ambientIntensity 1
          diffuseColor 1 1 1
          emissiveColor 1 1 1
          shininess 0
          specularColor 1 1 1
        }
        texture ImageTexture {
          url [
            "textures/hallway1segment2east.png"
          ]
        }
      }
      geometry Box {
        size 0.5 0.5 0.01
      }
    }
  ]
}
DEF H1S2W Solid {
  translation 6.70752 0.51 2.27621
  rotation 0 1 0 1.5708
  children [
    Shape {
      appearance Appearance {
        material Material {
          ambientIntensity 1
          diffuseColor 1 1 1
          emissiveColor 1 1 1
          shininess 0
          specularColor 1 1 1
        }
        texture ImageTexture {
          url [
            "textures/hallway1segment2west.png"
          ]
        }
      }
      geometry Box {
        size 0.5 0.5 0.01
      }
    }
  ]
}
DEF H1S1E Solid {
  translation 4.68752 0.51 3.61622
  rotation 0 1 0 1.5708
  children [
    Shape {
      appearance Appearance {
        material Material {
          ambientIntensity 1
          diffuseColor 1 1 1
          emissiveColor 1 1 1
          shininess 0
          specularColor 1 1 1
        }
        texture ImageTexture {
          url [
            "textures/hallway1segment1east.png"
          ]
        }
      }
      geometry Box {
        size 0.5 0.5 0.01
      }
    }
    Solid {
      rotation 1 0 0 1.5708
      children [
        Shape {
          appearance Appearance {
            material Material {
              ambientIntensity 1
              diffuseColor 0.901961 0 0
              shininess 0.3
            }
          }
          geometry Cylinder {
            height 0.02
            radius 0.05
          }
        }
      ]
    }
  ]
}
DEF H2S2W Solid {
  translation 6.70752 0.51 3.61621
  rotation 0 1 0 1.5708
  children [
    Shape {
      appearance Appearance {
        material Material {
          ambientIntensity 1
          diffuseColor 1 1 1
          emissiveColor 1 1 1
          shininess 0
          specularColor 1 1 1
        }
        texture ImageTexture {
          url [
            "textures/hallway1segment1west.png"
          ]
        }
      }
      geometry Box {
        size 0.5 0.5 0.01
      }
    }
  ]
}
DEF NAO_1 Nao {
  translation 5.69 0.334009 3.86
  rotation -1.69525e-09 0.707108 0.707106 3.1416
  cameraWidth 1280
  cameraHeight 960
  cameraPixelSize 0.25
}
SphericalSkyDome {
}
