#VRML_SIM V7.4.3 utf8
WorldInfo {
  info [
    "Description"
    "Author: first name last name <e-mail>"
    "Date: DD MMM YYYY"
  ]
}
Viewpoint {
  orientation 1 1.32183e-19 -3.20291e-19 4.70962
  position 4.01757 19.4971 -3.82424
}
Background {
  skyColor [
    0.4 0.7 1
  ]
}
DirectionalLight {
  ambientIntensity 1
  direction -0.33 -1 -0.5
  castShadows TRUE
}
Supervisor {
  controller "SupervisorController"
}
DEF NAO_BOT Nao {
  translation 0.825 0.334011 -3.825
}
Floor {
  size 100 100
}
DEF R31R34DOOR Robot {
  translation 4.84378 1.03 -1.57743
  rotation 0 -1 0 6.28318
  children [
    Solid {
      translation -0.15 0 0
      children [
        Shape {
          geometry Box {
            size 0.2 2 0.15
          }
        }
      ]
    }
    Solid {
      translation 1.1 0 0
      children [
        Shape {
          geometry Box {
            size 0.3 2 0.15
          }
        }
      ]
    }
    DEF STATIC_BODY Shape {
      appearance Appearance {
        material Material {
          diffuseColor 0.317647 0.317647 0.317647
        }
      }
      geometry Box {
        size 0.05 2.05 0.15
      }
    }
    DEF DOOR HingeJoint {
      jointParameters DEF r31r34 HingeJointParameters {
        axis 0 1 0
        anchor 0.05 0 0
        minStop -2.618
        maxStop 2.618
        staticFriction 0.5
      }
      device PositionSensor {
      }
      endPoint DEF r31r34bound Solid {
        translation 0.44 0 0
        children [
          Shape {
            appearance Appearance {
              texture ImageTexture {
                url [
                  "textures/single_door_common.png"
                ]
              }
            }
            geometry DEF DOOR_SHAPE Box {
              size 0.9 2 0.05
            }
          }
        ]
        boundingObject USE DOOR_SHAPE
        physics Physics {
          density -1
          mass 10
        }
      }
    }
  ]
}
DEF R21R24DOOR Robot {
  translation 4.83376 1.03 -6.07743
  rotation 0 -1 0 6.28318
  children [
    Solid {
      translation -0.15 0 0
      children [
        Shape {
          geometry Box {
            size 0.2 2 0.15
          }
        }
      ]
    }
    Solid {
      translation 1.1 0 0
      children [
        Shape {
          geometry Box {
            size 0.3 2 0.15
          }
        }
      ]
    }
    DEF STATIC_BODY Shape {
      appearance Appearance {
        material Material {
          diffuseColor 0.317647 0.317647 0.317647
        }
      }
      geometry Box {
        size 0.05 2.05 0.15
      }
    }
    DEF DOOR HingeJoint {
      jointParameters DEF r21r24 HingeJointParameters {
        axis 0 1 0
        anchor 0.05 0 0
        minStop -2.618
        maxStop 2.618
        staticFriction 0.5
      }
      device PositionSensor {
      }
      endPoint DEF r21r24bound Solid {
        translation 0.44 0 0
        children [
          Shape {
            appearance Appearance {
              texture ImageTexture {
                url [
                  "textures/single_door_common.png"
                ]
              }
            }
            geometry DEF DOOR_SHAPE Box {
              size 0.9 2 0.05
            }
          }
        ]
        boundingObject USE DOOR_SHAPE
        physics Physics {
          density -1
          mass 10
        }
      }
    }
  ]
}
DEF R13R14DOOR Robot {
  translation 1.60378 1.03 -4.80741
  rotation 0 -1 0 4.71239
  children [
    Solid {
      translation -0.15 0 0
      children [
        Shape {
          geometry Box {
            size 0.2 2 0.15
          }
        }
      ]
    }
    Solid {
      translation 1.1 0 0
      children [
        Shape {
          geometry Box {
            size 0.3 2 0.15
          }
        }
      ]
    }
    DEF STATIC_BODY Shape {
      appearance Appearance {
        material Material {
          diffuseColor 0.317647 0.317647 0.317647
        }
      }
      geometry Box {
        size 0.05 2.05 0.15
      }
    }
    DEF DOOR HingeJoint {
      jointParameters DEF r13r14 HingeJointParameters {
        axis 0 1 0
        anchor 0.05 0 0
        minStop -2.618
        maxStop 2.618
        staticFriction 0.5
      }
      device PositionSensor {
      }
      endPoint DEF r13r14bound Solid {
        translation 0.44 0 0
        children [
          Shape {
            appearance Appearance {
              texture ImageTexture {
                url [
                  "textures/single_door_common.png"
                ]
              }
            }
            geometry DEF DOOR_SHAPE Box {
              size 0.9 2 0.05
            }
          }
        ]
        boundingObject USE DOOR_SHAPE
        physics Physics {
          density -1
          mass 10
        }
      }
    }
  ]
}
DEF R11R12DOOR Robot {
  translation 1.60378 1.03 -7.32741
  rotation 0 1 0 4.71239
  children [
    Solid {
      translation -0.15 0 0
      children [
        Shape {
          geometry Box {
            size 0.2 2 0.15
          }
        }
      ]
    }
    Solid {
      translation 1.1 0 0
      children [
        Shape {
          geometry Box {
            size 0.3 2 0.15
          }
        }
      ]
    }
    DEF STATIC_BODY Shape {
      appearance Appearance {
        material Material {
          diffuseColor 0.317647 0.317647 0.317647
        }
      }
      geometry Box {
        size 0.05 2.05 0.15
      }
    }
    DEF DOOR HingeJoint {
      jointParameters DEF r11r12 HingeJointParameters {
        axis 0 1 0
        anchor 0.05 0 0
        minStop -2.618
        maxStop 2.618
        staticFriction 0.5
      }
      device PositionSensor {
      }
      endPoint DEF r11r12bound Solid {
        translation 0.44 0 0
        children [
          Shape {
            appearance Appearance {
              texture ImageTexture {
                url [
                  "textures/single_door_common.png"
                ]
              }
            }
            geometry DEF DOOR_SHAPE Box {
              size 0.9 2 0.05
            }
          }
        ]
        boundingObject USE DOOR_SHAPE
        physics Physics {
          density -1
          mass 10
        }
      }
    }
  ]
}
DEF R21R22DOOR Robot {
  translation 6.10378 1.03 -7.32741
  rotation 0 1 0 4.71239
  children [
    Solid {
      translation -0.15 0 0
      children [
        Shape {
          geometry Box {
            size 0.2 2 0.15
          }
        }
      ]
    }
    Solid {
      translation 1.1 0 0
      children [
        Shape {
          geometry Box {
            size 0.3 2 0.15
          }
        }
      ]
    }
    DEF STATIC_BODY Shape {
      appearance Appearance {
        material Material {
          diffuseColor 0.317647 0.317647 0.317647
        }
      }
      geometry Box {
        size 0.05 2.05 0.15
      }
    }
    DEF DOOR HingeJoint {
      jointParameters DEF r21r22 HingeJointParameters {
        axis 0 1 0
        anchor 0.05 0 0
        minStop -2.618
        maxStop 2.618
        staticFriction 0.5
      }
      device PositionSensor {
      }
      endPoint DEF r21r22bound Solid {
        translation 0.44 0 0
        children [
          Shape {
            appearance Appearance {
              texture ImageTexture {
                url [
                  "textures/single_door_common.png"
                ]
              }
            }
            geometry DEF DOOR_SHAPE Box {
              size 0.9 2 0.05
            }
          }
        ]
        boundingObject USE DOOR_SHAPE
        physics Physics {
          density -1
          mass 10
        }
      }
    }
  ]
}
DEF R42R43DOOR Robot {
  translation 2.84378 1.03 -1.57742
  rotation 0 -1 0 3.14159
  children [
    Solid {
      translation -0.15 0 0
      children [
        Shape {
          geometry Box {
            size 0.2 2 0.15
          }
        }
      ]
    }
    Solid {
      translation 1.1 0 0
      children [
        Shape {
          geometry Box {
            size 0.3 2 0.15
          }
        }
      ]
    }
    DEF STATIC_BODY Shape {
      appearance Appearance {
        material Material {
          diffuseColor 0.317647 0.317647 0.317647
        }
      }
      geometry Box {
        size 0.05 2.05 0.15
      }
    }
    DEF DOOR HingeJoint {
      jointParameters DEF r42r43 HingeJointParameters {
        axis 0 1 0
        anchor 0.05 0 0
        minStop -2.618
        maxStop 2.618
        staticFriction 0.5
      }
      device PositionSensor {
      }
      endPoint DEF r42r43bound Solid {
        translation 0.44 0 0
        children [
          Shape {
            appearance Appearance {
              texture ImageTexture {
                url [
                  "textures/single_door_common.png"
                ]
              }
            }
            geometry DEF DOOR_SHAPE Box {
              size 0.9 2 0.05
            }
          }
        ]
        boundingObject USE DOOR_SHAPE
        physics Physics {
          density -1
          mass 10
        }
      }
    }
  ]
}
DEF R12R13DOOR Robot {
  translation 2.85376 1.03 -6.06741
  rotation 0 -1 0 3.14159
  children [
    Solid {
      translation -0.15 0 0
      children [
        Shape {
          geometry Box {
            size 0.2 2 0.15
          }
        }
      ]
    }
    Solid {
      translation 1.1 0 0
      children [
        Shape {
          geometry Box {
            size 0.3 2 0.15
          }
        }
      ]
    }
    DEF STATIC_BODY Shape {
      appearance Appearance {
        material Material {
          diffuseColor 0.317647 0.317647 0.317647
        }
      }
      geometry Box {
        size 0.05 2.05 0.15
      }
    }
    DEF DOOR HingeJoint {
      jointParameters DEF r12r13 HingeJointParameters {
        axis 0 1 0
        anchor 0.05 0 0
        minStop -2.618
        maxStop 2.618
        staticFriction 0.5
      }
      device PositionSensor {
      }
      endPoint DEF r12r13bound Solid {
        translation 0.44 0 0
        children [
          Shape {
            appearance Appearance {
              texture ImageTexture {
                url [
                  "textures/single_door_common.png"
                ]
              }
            }
            geometry DEF DOOR_SHAPE Box {
              size 0.9 2 0.05
            }
          }
        ]
        boundingObject USE DOOR_SHAPE
        physics Physics {
          density -1
          mass 10
        }
      }
    }
  ]
}
DEF R32R33DOOR Robot {
  translation 7.34378 1.03 -1.57744
  rotation 0 -1 0 3.14159
  children [
    Solid {
      translation -0.15 0 0
      children [
        Shape {
          geometry Box {
            size 0.2 2 0.15
          }
        }
      ]
    }
    Solid {
      translation 1.1 0 0
      children [
        Shape {
          geometry Box {
            size 0.3 2 0.15
          }
        }
      ]
    }
    DEF STATIC_BODY Shape {
      appearance Appearance {
        material Material {
          diffuseColor 0.317647 0.317647 0.317647
        }
      }
      geometry Box {
        size 0.05 2.05 0.15
      }
    }
    DEF DOOR HingeJoint {
      jointParameters DEF r32r33 HingeJointParameters {
        axis 0 1 0
        anchor 0.05 0 0
        minStop -2.618
        maxStop 2.618
        staticFriction 0.5
      }
      device PositionSensor {
      }
      endPoint DEF r32r33bound Solid {
        translation 0.44 0 0
        children [
          Shape {
            appearance Appearance {
              texture ImageTexture {
                url [
                  "textures/single_door_common.png"
                ]
              }
            }
            geometry DEF DOOR_SHAPE Box {
              size 0.9 2 0.05
            }
          }
        ]
        boundingObject USE DOOR_SHAPE
        physics Physics {
          density -1
          mass 10
        }
      }
    }
  ]
}
DEF R22R23DOOR Robot {
  translation 7.34377 1.03 -6.07744
  rotation 0 -1 0 3.14159
  children [
    Solid {
      translation -0.15 0 0
      children [
        Shape {
          geometry Box {
            size 0.2 2 0.15
          }
        }
      ]
    }
    Solid {
      translation 1.1 0 0
      children [
        Shape {
          geometry Box {
            size 0.3 2 0.15
          }
        }
      ]
    }
    DEF STATIC_BODY Shape {
      appearance Appearance {
        material Material {
          diffuseColor 0.317647 0.317647 0.317647
        }
      }
      geometry Box {
        size 0.05 2.05 0.15
      }
    }
    DEF DOOR HingeJoint {
      jointParameters DEF r22r23 HingeJointParameters {
        axis 0 1 0
        anchor 0.05 0 0
        minStop -2.618
        maxStop 2.618
        staticFriction 0.5
      }
      device PositionSensor {
      }
      endPoint DEF r22r23bound Solid {
        translation 0.44 0 0
        children [
          Shape {
            appearance Appearance {
              texture ImageTexture {
                url [
                  "textures/single_door_common.png"
                ]
              }
            }
            geometry DEF DOOR_SHAPE Box {
              size 0.9 2 0.05
            }
          }
        ]
        boundingObject USE DOOR_SHAPE
        physics Physics {
          density -1
          mass 10
        }
      }
    }
  ]
}
DEF R41R44DOOR Robot {
  translation 0.343779 1.03 -1.5774
  rotation 0 -1 0 6.28318
  children [
    Solid {
      translation -0.15 0 0
      children [
        Shape {
          geometry Box {
            size 0.2 2 0.15
          }
        }
      ]
    }
    Solid {
      translation 1.1 0 0
      children [
        Shape {
          geometry Box {
            size 0.3 2 0.15
          }
        }
      ]
    }
    DEF STATIC_BODY Shape {
      appearance Appearance {
        material Material {
          diffuseColor 0.317647 0.317647 0.317647
        }
      }
      geometry Box {
        size 0.05 2.05 0.15
      }
    }
    DEF DOOR HingeJoint {
      jointParameters DEF r41r44 HingeJointParameters {
        axis 0 1 0
        anchor 0.05 0 0
        minStop -2.618
        maxStop 2.618
        staticFriction 0.5
      }
      device PositionSensor {
      }
      endPoint DEF r41r44bound Solid {
        translation 0.44 0 0
        children [
          Shape {
            appearance Appearance {
              texture ImageTexture {
                url [
                  "textures/single_door_common.png"
                ]
              }
            }
            geometry DEF DOOR_SHAPE Box {
              size 0.9 2 0.05
            }
          }
        ]
        boundingObject USE DOOR_SHAPE
        physics Physics {
          density -1
          mass 10
        }
      }
    }
  ]
}
DEF S03R41DOOR Robot {
  translation 0.313771 1.03 -3.0774
  rotation 0 -1 0 6.28318
  children [
    Solid {
      translation -0.15 0 0
      children [
        Shape {
          geometry Box {
            size 0.2 2 0.15
          }
        }
      ]
    }
    Solid {
      translation 1.1 0 0
      children [
        Shape {
          geometry Box {
            size 0.3 2 0.15
          }
        }
      ]
    }
    DEF STATIC_BODY Shape {
      appearance Appearance {
        material Material {
          diffuseColor 0.317647 0.317647 0.317647
        }
      }
      geometry Box {
        size 0.05 2.05 0.15
      }
    }
    DEF DOOR HingeJoint {
      jointParameters DEF s03r41 HingeJointParameters {
        axis 0 1 0
        anchor 0.05 0 0
        minStop -2.618
        maxStop 2.618
        staticFriction 0.5
      }
      device PositionSensor {
      }
      endPoint DEF s03r41bound Solid {
        translation 0.44 0 0
        children [
          Shape {
            appearance Appearance {
              texture ImageTexture {
                url [
                  "textures/single_door_common.png"
                ]
              }
            }
            geometry DEF DOOR_SHAPE Box {
              size 0.9 2 0.05
            }
          }
        ]
        boundingObject USE DOOR_SHAPE
        physics Physics {
          density -1
          mass 10
        }
      }
    }
  ]
}
DEF S03R14DOOR Robot {
  translation 0.313762 1.03 -4.5774
  rotation 0 -1 0 6.28318
  children [
    Solid {
      translation -0.15 0 0
      children [
        Shape {
          geometry Box {
            size 0.2 2 0.15
          }
        }
      ]
    }
    Solid {
      translation 1.1 0 0
      children [
        Shape {
          geometry Box {
            size 0.3 2 0.15
          }
        }
      ]
    }
    DEF STATIC_BODY Shape {
      appearance Appearance {
        material Material {
          diffuseColor 0.317647 0.317647 0.317647
        }
      }
      geometry Box {
        size 0.05 2.05 0.15
      }
    }
    DEF DOOR HingeJoint {
      jointParameters DEF s03r14 HingeJointParameters {
        axis 0 1 0
        anchor 0.05 0 0
        minStop -2.618
        maxStop 2.618
        staticFriction 0.5
      }
      device PositionSensor {
      }
      endPoint DEF s03r14bound Solid {
        translation 0.44 0 0
        children [
          Shape {
            appearance Appearance {
              texture ImageTexture {
                url [
                  "textures/single_door_common.png"
                ]
              }
            }
            geometry DEF DOOR_SHAPE Box {
              size 0.9 2 0.05
            }
          }
        ]
        boundingObject USE DOOR_SHAPE
        physics Physics {
          density -1
          mass 10
        }
      }
    }
  ]
}
DEF R11R14DOOR Robot {
  translation 0.333754 1.03 -6.0674
  rotation 0 -1 0 6.28318
  children [
    Solid {
      translation -0.15 0 0
      children [
        Shape {
          geometry Box {
            size 0.2 2 0.15
          }
        }
      ]
    }
    Solid {
      translation 1.1 0 0
      children [
        Shape {
          geometry Box {
            size 0.3 2 0.15
          }
        }
      ]
    }
    DEF STATIC_BODY Shape {
      appearance Appearance {
        material Material {
          diffuseColor 0.317647 0.317647 0.317647
        }
      }
      geometry Box {
        size 0.05 2.05 0.15
      }
    }
    DEF DOOR HingeJoint {
      jointParameters DEF r11r14 HingeJointParameters {
        axis 0 1 0
        anchor 0.05 0 0
        minStop -2.618
        maxStop 2.618
        staticFriction 0.5
      }
      device PositionSensor {
      }
      endPoint DEF r11r14bound Solid {
        translation 0.44 0 0
        children [
          Shape {
            appearance Appearance {
              texture ImageTexture {
                url [
                  "textures/single_door_common.png"
                ]
              }
            }
            geometry DEF DOOR_SHAPE Box {
              size 0.9 2 0.05
            }
          }
        ]
        boundingObject USE DOOR_SHAPE
        physics Physics {
          density -1
          mass 10
        }
      }
    }
  ]
}
DEF R23R24DOOR Robot {
  translation 6.10378 1.03 -4.80741
  rotation 0 -1 0 4.71239
  children [
    Solid {
      translation -0.15 0 0
      children [
        Shape {
          geometry Box {
            size 0.2 2 0.15
          }
        }
      ]
    }
    Solid {
      translation 1.1 0 0
      children [
        Shape {
          geometry Box {
            size 0.3 2 0.15
          }
        }
      ]
    }
    DEF STATIC_BODY Shape {
      appearance Appearance {
        material Material {
          diffuseColor 0.317647 0.317647 0.317647
        }
      }
      geometry Box {
        size 0.05 2.05 0.15
      }
    }
    DEF DOOR HingeJoint {
      jointParameters DEF r23r24 HingeJointParameters {
        axis 0 1 0
        anchor 0.05 0 0
        minStop -2.618
        maxStop 2.618
        staticFriction 0.5
      }
      device PositionSensor {
      }
      endPoint DEF r23r24bound Solid {
        translation 0.44 0 0
        children [
          Shape {
            appearance Appearance {
              texture ImageTexture {
                url [
                  "textures/single_door_common.png"
                ]
              }
            }
            geometry DEF DOOR_SHAPE Box {
              size 0.9 2 0.05
            }
          }
        ]
        boundingObject USE DOOR_SHAPE
        physics Physics {
          density -1
          mass 10
        }
      }
    }
  ]
}
DEF R31R32DOOR Robot {
  translation 6.10378 1.03 -2.79741
  rotation 0 1 0 4.71239
  children [
    Solid {
      translation -0.15 0 0
      children [
        Shape {
          geometry Box {
            size 0.2 2 0.15
          }
        }
      ]
    }
    Solid {
      translation 1.1 0 0
      children [
        Shape {
          geometry Box {
            size 0.3 2 0.15
          }
        }
      ]
    }
    DEF STATIC_BODY Shape {
      appearance Appearance {
        material Material {
          diffuseColor 0.317647 0.317647 0.317647
        }
      }
      geometry Box {
        size 0.05 2.05 0.15
      }
    }
    DEF DOOR HingeJoint {
      jointParameters DEF r31r32 HingeJointParameters {
        axis 0 1 0
        anchor 0.05 0 0
        minStop -2.618
        maxStop 2.618
        staticFriction 0.5
      }
      device PositionSensor {
      }
      endPoint DEF r31r32bound Solid {
        translation 0.44 0 0
        children [
          Shape {
            appearance Appearance {
              texture ImageTexture {
                url [
                  "textures/single_door_common.png"
                ]
              }
            }
            geometry DEF DOOR_SHAPE Box {
              size 0.9 2 0.05
            }
          }
        ]
        boundingObject USE DOOR_SHAPE
        physics Physics {
          density -1
          mass 10
        }
      }
    }
  ]
}
DEF R41R42DOOR Robot {
  translation 1.57378 1.03 -2.79741
  rotation 0 1 0 4.71239
  children [
    Solid {
      translation -0.15 0 0
      children [
        Shape {
          geometry Box {
            size 0.2 2 0.15
          }
        }
      ]
    }
    Solid {
      translation 1.1 0 0
      children [
        Shape {
          geometry Box {
            size 0.3 2 0.15
          }
        }
      ]
    }
    DEF STATIC_BODY Shape {
      appearance Appearance {
        material Material {
          diffuseColor 0.317647 0.317647 0.317647
        }
      }
      geometry Box {
        size 0.05 2.05 0.15
      }
    }
    DEF DOOR HingeJoint {
      jointParameters DEF r41r42 HingeJointParameters {
        axis 0 1 0
        anchor 0.05 0 0
        minStop -2.618
        maxStop 2.618
        staticFriction 0.5
      }
      device PositionSensor {
      }
      endPoint DEF r41r42bound Solid {
        translation 0.44 0 0
        children [
          Shape {
            appearance Appearance {
              texture ImageTexture {
                url [
                  "textures/single_door_common.png"
                ]
              }
            }
            geometry DEF DOOR_SHAPE Box {
              size 0.9 2 0.05
            }
          }
        ]
        boundingObject USE DOOR_SHAPE
        physics Physics {
          density -1
          mass 10
        }
      }
    }
  ]
}
DEF S01R34DOOR Robot {
  translation 4.5838 1.03 -0.31741
  rotation 0 1 0 1.5708
  children [
    Solid {
      translation -0.15 0 0
      children [
        Shape {
          geometry Box {
            size 0.2 2 0.15
          }
        }
      ]
    }
    Solid {
      translation 1.1 0 0
      children [
        Shape {
          geometry Box {
            size 0.3 2 0.15
          }
        }
      ]
    }
    DEF STATIC_BODY Shape {
      appearance Appearance {
        material Material {
          diffuseColor 0.317647 0.317647 0.317647
        }
      }
      geometry Box {
        size 0.05 2.05 0.15
      }
    }
    DEF DOOR HingeJoint {
      jointParameters DEF s01r34 HingeJointParameters {
        axis 0 1 0
        anchor 0.05 0 0
        minStop -2.618
        maxStop 2.618
        staticFriction 0.5
      }
      device PositionSensor {
      }
      endPoint DEF s01r34bound Solid {
        translation 0.44 0 0
        children [
          Shape {
            appearance Appearance {
              texture ImageTexture {
                url [
                  "textures/single_door_common.png"
                ]
              }
            }
            geometry DEF DOOR_SHAPE Box {
              size 0.9 2 0.05
            }
          }
        ]
        boundingObject USE DOOR_SHAPE
        physics Physics {
          density -1
          mass 10
        }
      }
    }
  ]
}
DEF R33R34DOOR Robot {
  translation 6.1038 1.03 -0.307415
  rotation 0 1 0 1.5708
  children [
    Solid {
      translation -0.15 0 0
      children [
        Shape {
          geometry Box {
            size 0.2 2 0.15
          }
        }
      ]
    }
    Solid {
      translation 1.1 0 0
      children [
        Shape {
          geometry Box {
            size 0.3 2 0.15
          }
        }
      ]
    }
    DEF STATIC_BODY Shape {
      appearance Appearance {
        material Material {
          diffuseColor 0.317647 0.317647 0.317647
        }
      }
      geometry Box {
        size 0.05 2.05 0.15
      }
    }
    DEF DOOR HingeJoint {
      jointParameters DEF r33r34 HingeJointParameters {
        axis 0 1 0
        anchor 0.05 0 0
        minStop -2.618
        maxStop 2.618
        staticFriction 0.5
      }
      device PositionSensor {
      }
      endPoint DEF r33r34bound Solid {
        translation 0.44 0 0
        children [
          Shape {
            appearance Appearance {
              texture ImageTexture {
                url [
                  "textures/single_door_common.png"
                ]
              }
            }
            geometry DEF DOOR_SHAPE Box {
              size 0.9 2 0.05
            }
          }
        ]
        boundingObject USE DOOR_SHAPE
        physics Physics {
          density -1
          mass 10
        }
      }
    }
  ]
}
DEF R43R44DOOR Robot {
  translation 1.5738 1.03 -0.307398
  rotation 0 1 0 1.5708
  children [
    Solid {
      translation -0.15 0 0
      children [
        Shape {
          geometry Box {
            size 0.2 2 0.15
          }
        }
      ]
    }
    Solid {
      translation 1.1 0 0
      children [
        Shape {
          geometry Box {
            size 0.3 2 0.15
          }
        }
      ]
    }
    DEF STATIC_BODY Shape {
      appearance Appearance {
        material Material {
          diffuseColor 0.317647 0.317647 0.317647
        }
      }
      geometry Box {
        size 0.05 2.05 0.15
      }
    }
    DEF DOOR HingeJoint {
      jointParameters DEF r43r44 HingeJointParameters {
        axis 0 1 0
        anchor 0.05 0 0
        minStop -2.618
        maxStop 2.618
        staticFriction 0.5
      }
      device PositionSensor {
      }
      endPoint DEF r43r44bound Solid {
        translation 0.44 0 0
        children [
          Shape {
            appearance Appearance {
              texture ImageTexture {
                url [
                  "textures/single_door_common.png"
                ]
              }
            }
            geometry DEF DOOR_SHAPE Box {
              size 0.9 2 0.05
            }
          }
        ]
        boundingObject USE DOOR_SHAPE
        physics Physics {
          density -1
          mass 10
        }
      }
    }
  ]
}
DEF S08R24DOOR Robot {
  translation 4.58378 1.03 -4.81741
  rotation 0 1 0 1.5708
  children [
    Solid {
      translation -0.15 0 0
      children [
        Shape {
          geometry Box {
            size 0.2 2 0.15
          }
        }
      ]
    }
    Solid {
      translation 1.1 0 0
      children [
        Shape {
          geometry Box {
            size 0.3 2 0.15
          }
        }
      ]
    }
    DEF STATIC_BODY Shape {
      appearance Appearance {
        material Material {
          diffuseColor 0.317647 0.317647 0.317647
        }
      }
      geometry Box {
        size 0.05 2.05 0.15
      }
    }
    DEF DOOR HingeJoint {
      jointParameters DEF s08r24 HingeJointParameters {
        axis 0 1 0
        anchor 0.05 0 0
        minStop -2.618
        maxStop 2.618
        staticFriction 0.5
      }
      device PositionSensor {
      }
      endPoint DEF s08r24bound Solid {
        translation 0.44 0 0
        children [
          Shape {
            appearance Appearance {
              texture ImageTexture {
                url [
                  "textures/single_door_common.png"
                ]
              }
            }
            geometry DEF DOOR_SHAPE Box {
              size 0.9 2 0.05
            }
          }
        ]
        boundingObject USE DOOR_SHAPE
        physics Physics {
          density -1
          mass 10
        }
      }
    }
  ]
}
DEF SWALL1 Solid {
  translation 0.825 1 0
  children [
    DEF WALL_SHAPE Shape {
      appearance Appearance {
      }
      geometry Box {
        size 1.5 2 0.15
      }
    }
  ]
}
DEF SWALL2 Solid {
  translation 2.325 1 0
  children [
    DEF WALL_SHAPE Shape {
      appearance Appearance {
      }
      geometry Box {
        size 1.5 2 0.15
      }
    }
  ]
}
DEF SWALL3 Solid {
  translation 3.825 1 0
  children [
    DEF WALL_SHAPE Shape {
      appearance Appearance {
      }
      geometry Box {
        size 1.5 2 0.15
      }
    }
  ]
}
DEF SWALL4 Solid {
  translation 5.325 1 0
  children [
    DEF WALL_SHAPE Shape {
      appearance Appearance {
      }
      geometry Box {
        size 1.5 2 0.15
      }
    }
  ]
}
DEF SWALL5 Solid {
  translation 6.825 1 0
  children [
    DEF WALL_SHAPE Shape {
      appearance Appearance {
      }
      geometry Box {
        size 1.5 2 0.15
      }
    }
  ]
}
DEF WWALL1 Solid {
  translation 0 1 -0.825
  rotation 0 1 0 1.5708
  children [
    DEF WALL_SHAPE Shape {
      appearance Appearance {
      }
      geometry Box {
        size 1.5 2 0.15
      }
    }
  ]
}
DEF WWALL2 Solid {
  translation 0 1 -2.325
  rotation 0 1 0 1.5708
  children [
    DEF WALL_SHAPE Shape {
      appearance Appearance {
      }
      geometry Box {
        size 1.5 2 0.15
      }
    }
  ]
}
DEF WWALL3 Solid {
  translation 0 1 -3.825
  rotation 0 1 0 1.5708
  children [
    DEF WALL_SHAPE Shape {
      appearance Appearance {
      }
      geometry Box {
        size 1.5 2 0.15
      }
    }
  ]
}
DEF WWALL4 Solid {
  translation 0 1 -5.325
  rotation 0 1 0 1.5708
  children [
    DEF WALL_SHAPE Shape {
      appearance Appearance {
      }
      geometry Box {
        size 1.5 2 0.15
      }
    }
  ]
}
DEF WWALL5 Solid {
  translation 0 1 -6.825
  rotation 0 1 0 1.5708
  children [
    DEF WALL_SHAPE Shape {
      appearance Appearance {
      }
      geometry Box {
        size 1.5 2 0.15
      }
    }
  ]
}
DEF NWALL1 Solid {
  translation 0.825 1 -7.65
  children [
    DEF WALL_SHAPE Shape {
      appearance Appearance {
      }
      geometry Box {
        size 1.5 2 0.15
      }
    }
  ]
}
DEF NWALL2 Solid {
  translation 2.325 1 -7.65
  children [
    DEF WALL_SHAPE Shape {
      appearance Appearance {
      }
      geometry Box {
        size 1.5 2 0.15
      }
    }
  ]
}
DEF NWALL3 Solid {
  translation 3.825 1 -7.65
  children [
    DEF WALL_SHAPE Shape {
      appearance Appearance {
      }
      geometry Box {
        size 1.5 2 0.15
      }
    }
  ]
}
DEF NWALL4 Solid {
  translation 5.325 1 -7.65
  children [
    DEF WALL_SHAPE Shape {
      appearance Appearance {
      }
      geometry Box {
        size 1.5 2 0.15
      }
    }
  ]
}
DEF NWALL5 Solid {
  translation 6.825 1 -7.65
  children [
    DEF WALL_SHAPE Shape {
      appearance Appearance {
      }
      geometry Box {
        size 1.5 2 0.15
      }
    }
  ]
}
DEF EWALL1 Solid {
  translation 7.575 1 -0.825
  rotation 0 1 0 1.5708
  children [
    DEF WALL_SHAPE Shape {
      appearance Appearance {
      }
      geometry Box {
        size 1.5 2 0.15
      }
    }
  ]
}
DEF EWALL2 Solid {
  translation 7.575 1 -2.325
  rotation 0 1 0 1.5708
  children [
    DEF WALL_SHAPE Shape {
      appearance Appearance {
      }
      geometry Box {
        size 1.5 2 0.15
      }
    }
  ]
}
DEF EWALL3 Solid {
  translation 7.575 1 -3.825
  rotation 0 1 0 1.5708
  children [
    DEF WALL_SHAPE Shape {
      appearance Appearance {
      }
      geometry Box {
        size 1.5 2 0.15
      }
    }
  ]
}
DEF EWALL4 Solid {
  translation 7.575 1 -5.325
  rotation 0 1 0 1.5708
  children [
    DEF WALL_SHAPE Shape {
      appearance Appearance {
      }
      geometry Box {
        size 1.5 2 0.15
      }
    }
  ]
}
DEF EWALL5 Solid {
  translation 7.575 1 -6.825
  rotation 0 1 0 1.5708
  children [
    DEF WALL_SHAPE Shape {
      appearance Appearance {
      }
      geometry Box {
        size 1.5 2 0.15
      }
    }
  ]
}
DEF ROOM1_NWALL Solid {
  translation 2.325 1 -3.075
  children [
    DEF WALL_SHAPE Shape {
      appearance Appearance {
      }
      geometry Box {
        size 1.5 2 0.15
      }
    }
  ]
}
DEF ROOM1_ROOM2_WALL Solid {
  translation 3.075 1 -2.325
  rotation 0 1 0 1.5708
  children [
    DEF WALL_SHAPE Shape {
      appearance Appearance {
      }
      geometry Box {
        size 1.5 2 0.15
      }
    }
  ]
}
DEF ROOM31_WWALL Solid {
  translation 4.575 1 -2.325
  rotation 0 1 0 1.5708
  children [
    DEF WALL_SHAPE Shape {
      appearance Appearance {
      }
      geometry Box {
        size 1.5 2 0.15
      }
    }
  ]
}
DEF ROOM43_EWALL Solid {
  translation 3.075 1 -0.825
  rotation 0 1 0 1.5708
  children [
    DEF WALL_SHAPE Shape {
      appearance Appearance {
      }
      geometry Box {
        size 1.5 2 0.15
      }
    }
  ]
}
DEF ROOM3_SWALL Solid {
  translation 2.325 1 -4.575
  children [
    DEF WALL_SHAPE Shape {
      appearance Appearance {
      }
      geometry Box {
        size 1.5 2 0.15
      }
    }
  ]
}
DEF WALLFILLER Solid {
  translation 1.415 1 -4.575
  children [
    DEF WALL_SHAPE Shape {
      appearance Appearance {
      }
      geometry Box {
        size 0.3 2 0.15
      }
    }
  ]
}
DEF WALLFILLER Solid {
  translation 1.415 1 -3.085
  children [
    DEF WALL_SHAPE Shape {
      appearance Appearance {
      }
      geometry Box {
        size 0.3 2 0.15
      }
    }
  ]
}
DEF WALLFILLER Solid {
  translation 1.595 1 -6.065
  children [
    DEF WALL_SHAPE Shape {
      appearance Appearance {
      }
      geometry Box {
        size 0.7 2 0.15
      }
    }
  ]
}
DEF WALLFILLER Solid {
  translation 6.095 1 -6.075
  children [
    DEF WALL_SHAPE Shape {
      appearance Appearance {
      }
      geometry Box {
        size 0.7 2 0.15
      }
    }
  ]
}
DEF WALLFILLER Solid {
  translation 6.095 1 -1.585
  children [
    DEF WALL_SHAPE Shape {
      appearance Appearance {
      }
      geometry Box {
        size 0.7 2 0.15
      }
    }
  ]
}
DEF WALLFILLER Solid {
  translation 6.095 1 -1.545
  rotation 0 1 0 1.5708
  children [
    DEF WALL_SHAPE Shape {
      appearance Appearance {
      }
      geometry Box {
        size 0.7 2 0.15
      }
    }
  ]
}
DEF WALLFILLER Solid {
  translation 1.575 1 -1.575
  children [
    DEF WALL_SHAPE Shape {
      appearance Appearance {
      }
      geometry Box {
        size 0.6 2 0.15
      }
    }
  ]
}
DEF WALLFILLER Solid {
  translation 1.595 1 -6.065
  rotation 0 1 0 4.71239
  children [
    DEF WALL_SHAPE Shape {
      appearance Appearance {
      }
      geometry Box {
        size 0.7 2 0.15
      }
    }
  ]
}
DEF WALLFILLER Solid {
  translation 6.105 1 -6.065
  rotation 0 1 0 4.71239
  children [
    DEF WALL_SHAPE Shape {
      appearance Appearance {
      }
      geometry Box {
        size 0.7 2 0.15
      }
    }
  ]
}
DEF WALLFILLER Solid {
  translation 1.575 1 -1.545
  rotation 0 1 0 4.71239
  children [
    DEF WALL_SHAPE Shape {
      appearance Appearance {
      }
      geometry Box {
        size 0.6 2 0.15
      }
    }
  ]
}
DEF WALLFILLER Solid {
  translation 0.145 1 -4.575
  children [
    DEF WALL_SHAPE Shape {
      appearance Appearance {
      }
      geometry Box {
        size 0.3 2 0.15
      }
    }
  ]
}
DEF WALLFILLER Solid {
  translation 0.145 1 -3.075
  children [
    DEF WALL_SHAPE Shape {
      appearance Appearance {
      }
      geometry Box {
        size 0.3 2 0.15
      }
    }
  ]
}
DEF WALLFILLER Solid {
  translation 0.145 1 -6.075
  children [
    DEF WALL_SHAPE Shape {
      appearance Appearance {
      }
      geometry Box {
        size 0.3 2 0.15
      }
    }
  ]
}
DEF WALLFILLER Solid {
  translation 2.995 1 -6.075
  children [
    DEF WALL_SHAPE Shape {
      appearance Appearance {
      }
      geometry Box {
        size 0.3 2 0.15
      }
    }
  ]
}
DEF WALLFILLER Solid {
  translation 4.655 1 -6.075
  children [
    DEF WALL_SHAPE Shape {
      appearance Appearance {
      }
      geometry Box {
        size 0.3 2 0.15
      }
    }
  ]
}
DEF WALLFILLER Solid {
  translation 7.465 1 -6.095
  children [
    DEF WALL_SHAPE Shape {
      appearance Appearance {
      }
      geometry Box {
        size 0.3 2 0.15
      }
    }
  ]
}
DEF WALLFILLER Solid {
  translation 1.595 1 -7.525
  rotation 0 1 0 4.71239
  children [
    DEF WALL_SHAPE Shape {
      appearance Appearance {
      }
      geometry Box {
        size 0.3 2 0.15
      }
    }
  ]
}
DEF WALLFILLER Solid {
  translation 6.095 1 -7.525
  rotation 0 1 0 4.71239
  children [
    DEF WALL_SHAPE Shape {
      appearance Appearance {
      }
      geometry Box {
        size 0.3 2 0.15
      }
    }
  ]
}
DEF WALLFILLER Solid {
  translation 6.095 1 -4.655
  rotation 0 1 0 4.71239
  children [
    DEF WALL_SHAPE Shape {
      appearance Appearance {
      }
      geometry Box {
        size 0.3 2 0.15
      }
    }
  ]
}
DEF WALLFILLER Solid {
  translation 4.585 1 -4.655
  rotation 0 1 0 4.71239
  children [
    DEF WALL_SHAPE Shape {
      appearance Appearance {
      }
      geometry Box {
        size 0.3 2 0.15
      }
    }
  ]
}
DEF WALLFILLER Solid {
  translation 4.585 1 -1.455
  rotation 0 1 0 4.71239
  children [
    DEF WALL_SHAPE Shape {
      appearance Appearance {
      }
      geometry Box {
        size 0.3 2 0.15
      }
    }
  ]
}
DEF WALLFILLER Solid {
  translation 4.585 1 -0.125
  rotation 0 1 0 4.71239
  children [
    DEF WALL_SHAPE Shape {
      appearance Appearance {
      }
      geometry Box {
        size 0.3 2 0.15
      }
    }
  ]
}
DEF WALLFILLER Solid {
  translation 6.105 1 -0.125002
  rotation 0 1 0 4.71239
  children [
    DEF WALL_SHAPE Shape {
      appearance Appearance {
      }
      geometry Box {
        size 0.3 2 0.15
      }
    }
  ]
}
DEF WALLFILLER Solid {
  translation 6.105 1 -2.985
  rotation 0 1 0 4.71239
  children [
    DEF WALL_SHAPE Shape {
      appearance Appearance {
      }
      geometry Box {
        size 0.3 2 0.15
      }
    }
  ]
}
DEF WALLFILLER Solid {
  translation 7.505 1 -1.585
  rotation 0 -1 0 3.14159
  children [
    DEF WALL_SHAPE Shape {
      appearance Appearance {
      }
      geometry Box {
        size 0.3 2 0.15
      }
    }
  ]
}
DEF WALLFILLER Solid {
  translation 4.665 1 -1.585
  rotation 0 -1 0 3.14159
  children [
    DEF WALL_SHAPE Shape {
      appearance Appearance {
      }
      geometry Box {
        size 0.3 2 0.15
      }
    }
  ]
}
DEF WALLFILLER Solid {
  translation 4.585 1 -5.885
  rotation 0 1 0 4.71239
  children [
    DEF WALL_SHAPE Shape {
      appearance Appearance {
      }
      geometry Box {
        size 0.3 2 0.15
      }
    }
  ]
}
DEF WALLFILLER Solid {
  translation 1.595 1 -4.645
  rotation 0 1 0 4.71239
  children [
    DEF WALL_SHAPE Shape {
      appearance Appearance {
      }
      geometry Box {
        size 0.3 2 0.15
      }
    }
  ]
}
DEF WALLFILLER Solid {
  translation 1.565 1 -3.005
  rotation 0 1 0 4.71239
  children [
    DEF WALL_SHAPE Shape {
      appearance Appearance {
      }
      geometry Box {
        size 0.3 2 0.15
      }
    }
  ]
}
DEF WALLFILLER Solid {
  translation 1.565 1 -0.155
  rotation 0 1 0 4.71239
  children [
    DEF WALL_SHAPE Shape {
      appearance Appearance {
      }
      geometry Box {
        size 0.3 2 0.15
      }
    }
  ]
}
DEF WALLFILLER Solid {
  translation 0.145003 1 -1.575
  rotation 0 -1 0 3.14159
  children [
    DEF WALL_SHAPE Shape {
      appearance Appearance {
      }
      geometry Box {
        size 0.3 2 0.15
      }
    }
  ]
}
DEF WALLFILLER Solid {
  translation 2.985 1 -1.575
  rotation 0 -1 0 3.14159
  children [
    DEF WALL_SHAPE Shape {
      appearance Appearance {
      }
      geometry Box {
        size 0.3 2 0.15
      }
    }
  ]
}
DEF ROOM3_ROOM4_WALL Solid {
  translation 3.075 1 -5.325
  rotation 0 1 0 1.5708
  children [
    DEF WALL_SHAPE Shape {
      appearance Appearance {
      }
      geometry Box {
        size 1.5 2 0.15
      }
    }
  ]
}
DEF ROOM3_ROOM4_WALL Solid {
  translation 3.07499 1 -6.825
  rotation 0 1 0 1.5708
  children [
    DEF WALL_SHAPE Shape {
      appearance Appearance {
      }
      geometry Box {
        size 1.5 2 0.15
      }
    }
  ]
}
DEF ROOM3_ROOM4_WALL Solid {
  translation 4.58499 1 -6.82501
  rotation 0 1 0 1.5708
  children [
    DEF WALL_SHAPE Shape {
      appearance Appearance {
      }
      geometry Box {
        size 1.5 2 0.15
      }
    }
  ]
}
DEF ROOM1_NWALL Solid {
  translation 6.825 1 -3.075
  children [
    DEF WALL_SHAPE Shape {
      appearance Appearance {
      }
      geometry Box {
        size 1.5 2 0.15
      }
    }
  ]
}
DEF ROOM31_NWALL Solid {
  translation 5.325 1 -3.075
  children [
    DEF WALL_SHAPE Shape {
      appearance Appearance {
      }
      geometry Box {
        size 1.5 2 0.15
      }
    }
  ]
}
DEF ROOM3_SWALL Solid {
  translation 6.825 1 -4.575
  children [
    DEF WALL_SHAPE Shape {
      appearance Appearance {
      }
      geometry Box {
        size 1.5 2 0.15
      }
    }
  ]
}
DEF ROOM3_SWALL Solid {
  translation 5.325 1 -4.575
  children [
    DEF WALL_SHAPE Shape {
      appearance Appearance {
      }
      geometry Box {
        size 1.5 2 0.15
      }
    }
  ]
}
