#VRML_SIM V7.4.3 utf8
WorldInfo {
  info [
    "Description"
    "Author: first name last name <e-mail>"
    "Date: DD MMM YYYY"
  ]
}
Viewpoint {
  orientation 1 1.32183e-19 -3.20291e-19 4.70962
  position 4.61757 18.9569 -3.90275
}
Background {
  skyColor [
    0.4 0.7 1
  ]
}
DirectionalLight {
  ambientIntensity 1
  direction -0.33 -1 -0.5
  castShadows TRUE
}
Supervisor {
  controller "SupervisorController"
}
DEF NAO_BOT Nao {
  translation 0.825 0.334 -6.825
}
Floor {
  size 100 100
}
DEF R31R34DOOR Robot {
  translation 4.84378 1.03 -1.57743
  rotation 0 -1 0 6.28318
  children [
    Solid {
      translation -0.15 0 0
      children [
        Shape {
          geometry Box {
            size 0.2 2 0.15
          }
        }
      ]
    }
    Solid {
      translation 1.1 0 0
      children [
        Shape {
          geometry Box {
            size 0.3 2 0.15
          }
        }
      ]
    }
    DEF STATIC_BODY Shape {
      appearance Appearance {
        material Material {
          diffuseColor 0.317647 0.317647 0.317647
        }
      }
      geometry Box {
        size 0.05 2.05 0.15
      }
    }
    DEF DOOR HingeJoint {
      jointParameters DEF s02r01 HingeJointParameters {
        axis 0 1 0
        anchor 0.05 0 0
        minStop -2.618
        maxStop 2.618
        staticFriction 0.5
      }
      device PositionSensor {
      }
      endPoint Solid {
        translation 0.44 0 0
        children [
          Shape {
            appearance Appearance {
              texture ImageTexture {
                url [
                  "textures/single_door_common.png"
                ]
              }
            }
            geometry DEF DOOR_SHAPE Box {
              size 0.9 2 0.05
            }
          }
        ]
        boundingObject USE DOOR_SHAPE
        physics Physics {
          density -1
          mass 10
        }
      }
    }
  ]
}
DEF R21R24DOOR Robot {
  translation 4.83376 1.03 -6.07743
  rotation 0 -1 0 6.28318
  children [
    Solid {
      translation -0.15 0 0
      children [
        Shape {
          geometry Box {
            size 0.2 2 0.15
          }
        }
      ]
    }
    Solid {
      translation 1.1 0 0
      children [
        Shape {
          geometry Box {
            size 0.3 2 0.15
          }
        }
      ]
    }
    DEF STATIC_BODY Shape {
      appearance Appearance {
        material Material {
          diffuseColor 0.317647 0.317647 0.317647
        }
      }
      geometry Box {
        size 0.05 2.05 0.15
      }
    }
    DEF DOOR HingeJoint {
      jointParameters DEF s02r01 HingeJointParameters {
        axis 0 1 0
        anchor 0.05 0 0
        minStop -2.618
        maxStop 2.618
        staticFriction 0.5
      }
      device PositionSensor {
      }
      endPoint Solid {
        translation 0.44 0 0
        children [
          Shape {
            appearance Appearance {
              texture ImageTexture {
                url [
                  "textures/single_door_common.png"
                ]
              }
            }
            geometry DEF DOOR_SHAPE Box {
              size 0.9 2 0.05
            }
          }
        ]
        boundingObject USE DOOR_SHAPE
        physics Physics {
          density -1
          mass 10
        }
      }
    }
  ]
}
DEF ROOF RectangleArena {
  translation 0 -1 0
}
DEF R13R14DOOR Robot {
  translation 1.60378 1.03 -4.80741
  rotation 0 -1 0 4.71239
  children [
    Solid {
      translation -0.15 0 0
      children [
        Shape {
          geometry Box {
            size 0.2 2 0.15
          }
        }
      ]
    }
    Solid {
      translation 1.1 0 0
      children [
        Shape {
          geometry Box {
            size 0.3 2 0.15
          }
        }
      ]
    }
    DEF STATIC_BODY Shape {
      appearance Appearance {
        material Material {
          diffuseColor 0.317647 0.317647 0.317647
        }
      }
      geometry Box {
        size 0.05 2.05 0.15
      }
    }
    DEF DOOR HingeJoint {
      jointParameters DEF s18r03 HingeJointParameters {
        axis 0 1 0
        anchor 0.05 0 0
        minStop -2.618
        maxStop 2.618
        staticFriction 0.5
      }
      device PositionSensor {
      }
      endPoint Solid {
        translation 0.44 0 0
        children [
          Shape {
            appearance Appearance {
              texture ImageTexture {
                url [
                  "textures/single_door_common.png"
                ]
              }
            }
            geometry DEF DOOR_SHAPE Box {
              size 0.9 2 0.05
            }
          }
        ]
        boundingObject USE DOOR_SHAPE
        physics Physics {
          density -1
          mass 10
        }
      }
    }
  ]
}
DEF R11R12DOOR Robot {
  translation 1.60378 1.03 -7.32741
  rotation 0 1 0 4.71239
  children [
    Solid {
      translation -0.15 0 0
      children [
        Shape {
          geometry Box {
            size 0.2 2 0.15
          }
        }
      ]
    }
    Solid {
      translation 1.1 0 0
      children [
        Shape {
          geometry Box {
            size 0.3 2 0.15
          }
        }
      ]
    }
    DEF STATIC_BODY Shape {
      appearance Appearance {
        material Material {
          diffuseColor 0.317647 0.317647 0.317647
        }
      }
      geometry Box {
        size 0.05 2.05 0.15
      }
    }
    DEF DOOR HingeJoint {
      jointParameters DEF s18r03 HingeJointParameters {
        axis 0 1 0
        anchor 0.05 0 0
        minStop -2.618
        maxStop 2.618
        staticFriction 0.5
      }
      device PositionSensor {
      }
      endPoint Solid {
        translation 0.44 0 0
        children [
          Shape {
            appearance Appearance {
              texture ImageTexture {
                url [
                  "textures/single_door_common.png"
                ]
              }
            }
            geometry DEF DOOR_SHAPE Box {
              size 0.9 2 0.05
            }
          }
        ]
        boundingObject USE DOOR_SHAPE
        physics Physics {
          density -1
          mass 10
        }
      }
    }
  ]
}
DEF R21R22DOOR Robot {
  translation 6.10378 1.03 -7.32741
  rotation 0 1 0 4.71239
  children [
    Solid {
      translation -0.15 0 0
      children [
        Shape {
          geometry Box {
            size 0.2 2 0.15
          }
        }
      ]
    }
    Solid {
      translation 1.1 0 0
      children [
        Shape {
          geometry Box {
            size 0.3 2 0.15
          }
        }
      ]
    }
    DEF STATIC_BODY Shape {
      appearance Appearance {
        material Material {
          diffuseColor 0.317647 0.317647 0.317647
        }
      }
      geometry Box {
        size 0.05 2.05 0.15
      }
    }
    DEF DOOR HingeJoint {
      jointParameters DEF s18r03 HingeJointParameters {
        axis 0 1 0
        anchor 0.05 0 0
        minStop -2.618
        maxStop 2.618
        staticFriction 0.5
      }
      device PositionSensor {
      }
      endPoint Solid {
        translation 0.44 0 0
        children [
          Shape {
            appearance Appearance {
              texture ImageTexture {
                url [
                  "textures/single_door_common.png"
                ]
              }
            }
            geometry DEF DOOR_SHAPE Box {
              size 0.9 2 0.05
            }
          }
        ]
        boundingObject USE DOOR_SHAPE
        physics Physics {
          density -1
          mass 10
        }
      }
    }
  ]
}
DEF R42R43DOOR Robot {
  translation 2.79378 1.03 -1.57742
  rotation 0 -1 0 3.14159
  children [
    Solid {
      translation -0.15 0 0
      children [
        Shape {
          geometry Box {
            size 0.2 2 0.15
          }
        }
      ]
    }
    Solid {
      translation 1.1 0 0
      children [
        Shape {
          geometry Box {
            size 0.3 2 0.15
          }
        }
      ]
    }
    DEF STATIC_BODY Shape {
      appearance Appearance {
        material Material {
          diffuseColor 0.317647 0.317647 0.317647
        }
      }
      geometry Box {
        size 0.05 2.05 0.15
      }
    }
    DEF DOOR HingeJoint {
      jointParameters DEF s02r01 HingeJointParameters {
        axis 0 1 0
        anchor 0.05 0 0
        minStop -2.618
        maxStop 2.618
        staticFriction 0.5
      }
      device PositionSensor {
      }
      endPoint Solid {
        translation 0.44 0 0
        children [
          Shape {
            appearance Appearance {
              texture ImageTexture {
                url [
                  "textures/single_door_common.png"
                ]
              }
            }
            geometry DEF DOOR_SHAPE Box {
              size 0.9 2 0.05
            }
          }
        ]
        boundingObject USE DOOR_SHAPE
        physics Physics {
          density -1
          mass 10
        }
      }
    }
  ]
}
DEF R12R13DOOR Robot {
  translation 2.79376 1.03 -6.06741
  rotation 0 -1 0 3.14159
  children [
    Solid {
      translation -0.15 0 0
      children [
        Shape {
          geometry Box {
            size 0.2 2 0.15
          }
        }
      ]
    }
    Solid {
      translation 1.1 0 0
      children [
        Shape {
          geometry Box {
            size 0.3 2 0.15
          }
        }
      ]
    }
    DEF STATIC_BODY Shape {
      appearance Appearance {
        material Material {
          diffuseColor 0.317647 0.317647 0.317647
        }
      }
      geometry Box {
        size 0.05 2.05 0.15
      }
    }
    DEF DOOR HingeJoint {
      jointParameters DEF s02r01 HingeJointParameters {
        axis 0 1 0
        anchor 0.05 0 0
        minStop -2.618
        maxStop 2.618
        staticFriction 0.5
      }
      device PositionSensor {
      }
      endPoint Solid {
        translation 0.44 0 0
        children [
          Shape {
            appearance Appearance {
              texture ImageTexture {
                url [
                  "textures/single_door_common.png"
                ]
              }
            }
            geometry DEF DOOR_SHAPE Box {
              size 0.9 2 0.05
            }
          }
        ]
        boundingObject USE DOOR_SHAPE
        physics Physics {
          density -1
          mass 10
        }
      }
    }
  ]
}
DEF R32R33DOOR Robot {
  translation 7.34378 1.03 -1.57744
  rotation 0 -1 0 3.14159
  children [
    Solid {
      translation -0.15 0 0
      children [
        Shape {
          geometry Box {
            size 0.2 2 0.15
          }
        }
      ]
    }
    Solid {
      translation 1.1 0 0
      children [
        Shape {
          geometry Box {
            size 0.3 2 0.15
          }
        }
      ]
    }
    DEF STATIC_BODY Shape {
      appearance Appearance {
        material Material {
          diffuseColor 0.317647 0.317647 0.317647
        }
      }
      geometry Box {
        size 0.05 2.05 0.15
      }
    }
    DEF DOOR HingeJoint {
      jointParameters DEF s02r01 HingeJointParameters {
        axis 0 1 0
        anchor 0.05 0 0
        minStop -2.618
        maxStop 2.618
        staticFriction 0.5
      }
      device PositionSensor {
      }
      endPoint Solid {
        translation 0.44 0 0
        children [
          Shape {
            appearance Appearance {
              texture ImageTexture {
                url [
                  "textures/single_door_common.png"
                ]
              }
            }
            geometry DEF DOOR_SHAPE Box {
              size 0.9 2 0.05
            }
          }
        ]
        boundingObject USE DOOR_SHAPE
        physics Physics {
          density -1
          mass 10
        }
      }
    }
  ]
}
DEF R22R23DOOR Robot {
  translation 7.34377 1.03 -6.07744
  rotation 0 -1 0 3.14159
  children [
    Solid {
      translation -0.15 0 0
      children [
        Shape {
          geometry Box {
            size 0.2 2 0.15
          }
        }
      ]
    }
    Solid {
      translation 1.1 0 0
      children [
        Shape {
          geometry Box {
            size 0.3 2 0.15
          }
        }
      ]
    }
    DEF STATIC_BODY Shape {
      appearance Appearance {
        material Material {
          diffuseColor 0.317647 0.317647 0.317647
        }
      }
      geometry Box {
        size 0.05 2.05 0.15
      }
    }
    DEF DOOR HingeJoint {
      jointParameters DEF s02r01 HingeJointParameters {
        axis 0 1 0
        anchor 0.05 0 0
        minStop -2.618
        maxStop 2.618
        staticFriction 0.5
      }
      device PositionSensor {
      }
      endPoint Solid {
        translation 0.44 0 0
        children [
          Shape {
            appearance Appearance {
              texture ImageTexture {
                url [
                  "textures/single_door_common.png"
                ]
              }
            }
            geometry DEF DOOR_SHAPE Box {
              size 0.9 2 0.05
            }
          }
        ]
        boundingObject USE DOOR_SHAPE
        physics Physics {
          density -1
          mass 10
        }
      }
    }
  ]
}
DEF R41R44DOOR Robot {
  translation 0.313779 1.03 -1.5774
  rotation 0 -1 0 6.28318
  children [
    Solid {
      translation -0.15 0 0
      children [
        Shape {
          geometry Box {
            size 0.2 2 0.15
          }
        }
      ]
    }
    Solid {
      translation 1.1 0 0
      children [
        Shape {
          geometry Box {
            size 0.3 2 0.15
          }
        }
      ]
    }
    DEF STATIC_BODY Shape {
      appearance Appearance {
        material Material {
          diffuseColor 0.317647 0.317647 0.317647
        }
      }
      geometry Box {
        size 0.05 2.05 0.15
      }
    }
    DEF DOOR HingeJoint {
      jointParameters DEF s02r01 HingeJointParameters {
        axis 0 1 0
        anchor 0.05 0 0
        minStop -2.618
        maxStop 2.618
        staticFriction 0.5
      }
      device PositionSensor {
      }
      endPoint Solid {
        translation 0.44 0 0
        children [
          Shape {
            appearance Appearance {
              texture ImageTexture {
                url [
                  "textures/single_door_common.png"
                ]
              }
            }
            geometry DEF DOOR_SHAPE Box {
              size 0.9 2 0.05
            }
          }
        ]
        boundingObject USE DOOR_SHAPE
        physics Physics {
          density -1
          mass 10
        }
      }
    }
  ]
}
DEF R4DOOR Robot {
  translation 0.313771 1.03 -3.0774
  rotation 0 -1 0 6.28318
  children [
    Solid {
      translation -0.15 0 0
      children [
        Shape {
          geometry Box {
            size 0.2 2 0.15
          }
        }
      ]
    }
    Solid {
      translation 1.1 0 0
      children [
        Shape {
          geometry Box {
            size 0.3 2 0.15
          }
        }
      ]
    }
    DEF STATIC_BODY Shape {
      appearance Appearance {
        material Material {
          diffuseColor 0.317647 0.317647 0.317647
        }
      }
      geometry Box {
        size 0.05 2.05 0.15
      }
    }
    DEF DOOR HingeJoint {
      jointParameters DEF s02r01 HingeJointParameters {
        axis 0 1 0
        anchor 0.05 0 0
        minStop -2.618
        maxStop 2.618
        staticFriction 0.5
      }
      device PositionSensor {
      }
      endPoint Solid {
        translation 0.44 0 0
        children [
          Shape {
            appearance Appearance {
              texture ImageTexture {
                url [
                  "textures/single_door_common.png"
                ]
              }
            }
            geometry DEF DOOR_SHAPE Box {
              size 0.9 2 0.05
            }
          }
        ]
        boundingObject USE DOOR_SHAPE
        physics Physics {
          density -1
          mass 10
        }
      }
    }
  ]
}
DEF R1DOOR Robot {
  translation 0.313762 1.03 -4.5774
  rotation 0 -1 0 6.28318
  children [
    Solid {
      translation -0.15 0 0
      children [
        Shape {
          geometry Box {
            size 0.2 2 0.15
          }
        }
      ]
    }
    Solid {
      translation 1.1 0 0
      children [
        Shape {
          geometry Box {
            size 0.3 2 0.15
          }
        }
      ]
    }
    DEF STATIC_BODY Shape {
      appearance Appearance {
        material Material {
          diffuseColor 0.317647 0.317647 0.317647
        }
      }
      geometry Box {
        size 0.05 2.05 0.15
      }
    }
    DEF DOOR HingeJoint {
      jointParameters DEF s02r01 HingeJointParameters {
        axis 0 1 0
        anchor 0.05 0 0
        minStop -2.618
        maxStop 2.618
        staticFriction 0.5
      }
      device PositionSensor {
      }
      endPoint DEF s02r01bound Solid {
        translation 0.44 0 0
        children [
          Shape {
            appearance Appearance {
              texture ImageTexture {
                url [
                  "textures/single_door_common.png"
                ]
              }
            }
            geometry DEF DOOR_SHAPE Box {
              size 0.9 2 0.05
            }
          }
        ]
        boundingObject USE DOOR_SHAPE
        physics Physics {
          density -1
          mass 10
        }
      }
    }
  ]
}
DEF R11R14DOOR Robot {
  translation 0.313754 1.03 -6.0674
  rotation 0 -1 0 6.28318
  children [
    Solid {
      translation -0.15 0 0
      children [
        Shape {
          geometry Box {
            size 0.2 2 0.15
          }
        }
      ]
    }
    Solid {
      translation 1.1 0 0
      children [
        Shape {
          geometry Box {
            size 0.3 2 0.15
          }
        }
      ]
    }
    DEF STATIC_BODY Shape {
      appearance Appearance {
        material Material {
          diffuseColor 0.317647 0.317647 0.317647
        }
      }
      geometry Box {
        size 0.05 2.05 0.15
      }
    }
    DEF DOOR HingeJoint {
      jointParameters DEF s02r01 HingeJointParameters {
        axis 0 1 0
        anchor 0.05 0 0
        minStop -2.618
        maxStop 2.618
        staticFriction 0.5
      }
      device PositionSensor {
      }
      endPoint Solid {
        translation 0.44 0 0
        children [
          Shape {
            appearance Appearance {
              texture ImageTexture {
                url [
                  "textures/single_door_common.png"
                ]
              }
            }
            geometry DEF DOOR_SHAPE Box {
              size 0.9 2 0.05
            }
          }
        ]
        boundingObject USE DOOR_SHAPE
        physics Physics {
          density -1
          mass 10
        }
      }
    }
  ]
}
DEF R23R24DOOR Robot {
  translation 6.10378 1.03 -4.80741
  rotation 0 -1 0 4.71239
  children [
    Solid {
      translation -0.15 0 0
      children [
        Shape {
          geometry Box {
            size 0.2 2 0.15
          }
        }
      ]
    }
    Solid {
      translation 1.1 0 0
      children [
        Shape {
          geometry Box {
            size 0.3 2 0.15
          }
        }
      ]
    }
    DEF STATIC_BODY Shape {
      appearance Appearance {
        material Material {
          diffuseColor 0.317647 0.317647 0.317647
        }
      }
      geometry Box {
        size 0.05 2.05 0.15
      }
    }
    DEF DOOR HingeJoint {
      jointParameters DEF s19r07 HingeJointParameters {
        axis 0 1 0
        anchor 0.05 0 0
        minStop -2.618
        maxStop 2.618
        staticFriction 0.5
      }
      device PositionSensor {
      }
      endPoint Solid {
        translation 0.44 0 0
        children [
          Shape {
            appearance Appearance {
              texture ImageTexture {
                url [
                  "textures/single_door_common.png"
                ]
              }
            }
            geometry DEF DOOR_SHAPE Box {
              size 0.9 2 0.05
            }
          }
        ]
        boundingObject USE DOOR_SHAPE
        physics Physics {
          density -1
          mass 10
        }
      }
    }
  ]
}
DEF R31R32DOOR Robot {
  translation 6.10378 1.03 -2.79741
  rotation 0 1 0 4.71239
  children [
    Solid {
      translation -0.15 0 0
      children [
        Shape {
          geometry Box {
            size 0.2 2 0.15
          }
        }
      ]
    }
    Solid {
      translation 1.1 0 0
      children [
        Shape {
          geometry Box {
            size 0.3 2 0.15
          }
        }
      ]
    }
    DEF STATIC_BODY Shape {
      appearance Appearance {
        material Material {
          diffuseColor 0.317647 0.317647 0.317647
        }
      }
      geometry Box {
        size 0.05 2.05 0.15
      }
    }
    DEF DOOR HingeJoint {
      jointParameters DEF s09r07 HingeJointParameters {
        axis 0 1 0
        anchor 0.05 0 0
        minStop -2.618
        maxStop 2.618
        staticFriction 0.5
      }
      device PositionSensor {
      }
      endPoint Solid {
        translation 0.44 0 0
        children [
          Shape {
            appearance Appearance {
              texture ImageTexture {
                url [
                  "textures/single_door_common.png"
                ]
              }
            }
            geometry DEF DOOR_SHAPE Box {
              size 0.9 2 0.05
            }
          }
        ]
        boundingObject USE DOOR_SHAPE
        physics Physics {
          density -1
          mass 10
        }
      }
    }
  ]
}
DEF R41R42DOOR Robot {
  translation 1.57378 1.03 -2.79741
  rotation 0 1 0 4.71239
  children [
    Solid {
      translation -0.15 0 0
      children [
        Shape {
          geometry Box {
            size 0.2 2 0.15
          }
        }
      ]
    }
    Solid {
      translation 1.1 0 0
      children [
        Shape {
          geometry Box {
            size 0.3 2 0.15
          }
        }
      ]
    }
    DEF STATIC_BODY Shape {
      appearance Appearance {
        material Material {
          diffuseColor 0.317647 0.317647 0.317647
        }
      }
      geometry Box {
        size 0.05 2.05 0.15
      }
    }
    DEF DOOR HingeJoint {
      jointParameters DEF s09r07 HingeJointParameters {
        axis 0 1 0
        anchor 0.05 0 0
        minStop -2.618
        maxStop 2.618
        staticFriction 0.5
      }
      device PositionSensor {
      }
      endPoint Solid {
        translation 0.44 0 0
        children [
          Shape {
            appearance Appearance {
              texture ImageTexture {
                url [
                  "textures/single_door_common.png"
                ]
              }
            }
            geometry DEF DOOR_SHAPE Box {
              size 0.9 2 0.05
            }
          }
        ]
        boundingObject USE DOOR_SHAPE
        physics Physics {
          density -1
          mass 10
        }
      }
    }
  ]
}
DEF R3DOOR Robot {
  translation 4.5838 1.03 -0.31741
  rotation 0 1 0 1.5708
  children [
    Solid {
      translation -0.15 0 0
      children [
        Shape {
          geometry Box {
            size 0.2 2 0.15
          }
        }
      ]
    }
    Solid {
      translation 1.1 0 0
      children [
        Shape {
          geometry Box {
            size 0.3 2 0.15
          }
        }
      ]
    }
    DEF STATIC_BODY Shape {
      appearance Appearance {
        material Material {
          diffuseColor 0.317647 0.317647 0.317647
        }
      }
      geometry Box {
        size 0.05 2.05 0.15
      }
    }
    DEF DOOR HingeJoint {
      jointParameters DEF s09r02 HingeJointParameters {
        axis 0 1 0
        anchor 0.05 0 0
        minStop -2.618
        maxStop 2.618
        staticFriction 0.5
      }
      device PositionSensor {
      }
      endPoint Solid {
        translation 0.44 0 0
        children [
          Shape {
            appearance Appearance {
              texture ImageTexture {
                url [
                  "textures/single_door_common.png"
                ]
              }
            }
            geometry DEF DOOR_SHAPE Box {
              size 0.9 2 0.05
            }
          }
        ]
        boundingObject USE DOOR_SHAPE
        physics Physics {
          density -1
          mass 10
        }
      }
    }
  ]
}
DEF R33R34DOOR Robot {
  translation 6.1038 1.03 -0.307415
  rotation 0 1 0 1.5708
  children [
    Solid {
      translation -0.15 0 0
      children [
        Shape {
          geometry Box {
            size 0.2 2 0.15
          }
        }
      ]
    }
    Solid {
      translation 1.1 0 0
      children [
        Shape {
          geometry Box {
            size 0.3 2 0.15
          }
        }
      ]
    }
    DEF STATIC_BODY Shape {
      appearance Appearance {
        material Material {
          diffuseColor 0.317647 0.317647 0.317647
        }
      }
      geometry Box {
        size 0.05 2.05 0.15
      }
    }
    DEF DOOR HingeJoint {
      jointParameters DEF s09r02 HingeJointParameters {
        axis 0 1 0
        anchor 0.05 0 0
        minStop -2.618
        maxStop 2.618
        staticFriction 0.5
      }
      device PositionSensor {
      }
      endPoint Solid {
        translation 0.44 0 0
        children [
          Shape {
            appearance Appearance {
              texture ImageTexture {
                url [
                  "textures/single_door_common.png"
                ]
              }
            }
            geometry DEF DOOR_SHAPE Box {
              size 0.9 2 0.05
            }
          }
        ]
        boundingObject USE DOOR_SHAPE
        physics Physics {
          density -1
          mass 10
        }
      }
    }
  ]
}
DEF R43R44DOOR Robot {
  translation 1.5738 1.03 -0.307398
  rotation 0 1 0 1.5708
  children [
    Solid {
      translation -0.15 0 0
      children [
        Shape {
          geometry Box {
            size 0.2 2 0.15
          }
        }
      ]
    }
    Solid {
      translation 1.1 0 0
      children [
        Shape {
          geometry Box {
            size 0.3 2 0.15
          }
        }
      ]
    }
    DEF STATIC_BODY Shape {
      appearance Appearance {
        material Material {
          diffuseColor 0.317647 0.317647 0.317647
        }
      }
      geometry Box {
        size 0.05 2.05 0.15
      }
    }
    DEF DOOR HingeJoint {
      jointParameters DEF s09r02 HingeJointParameters {
        axis 0 1 0
        anchor 0.05 0 0
        minStop -2.618
        maxStop 2.618
        staticFriction 0.5
      }
      device PositionSensor {
      }
      endPoint Solid {
        translation 0.44 0 0
        children [
          Shape {
            appearance Appearance {
              texture ImageTexture {
                url [
                  "textures/single_door_common.png"
                ]
              }
            }
            geometry DEF DOOR_SHAPE Box {
              size 0.9 2 0.05
            }
          }
        ]
        boundingObject USE DOOR_SHAPE
        physics Physics {
          density -1
          mass 10
        }
      }
    }
  ]
}
DEF R2DOOR Robot {
  translation 4.58378 1.03 -4.81741
  rotation 0 1 0 1.5708
  children [
    Solid {
      translation -0.15 0 0
      children [
        Shape {
          geometry Box {
            size 0.2 2 0.15
          }
        }
      ]
    }
    Solid {
      translation 1.1 0 0
      children [
        Shape {
          geometry Box {
            size 0.3 2 0.15
          }
        }
      ]
    }
    DEF STATIC_BODY Shape {
      appearance Appearance {
        material Material {
          diffuseColor 0.317647 0.317647 0.317647
        }
      }
      geometry Box {
        size 0.05 2.05 0.15
      }
    }
    DEF DOOR HingeJoint {
      jointParameters DEF s19r04 HingeJointParameters {
        axis 0 1 0
        anchor 0.05 0 0
        minStop -2.618
        maxStop 2.618
        staticFriction 0.5
      }
      device PositionSensor {
      }
      endPoint Solid {
        translation 0.44 0 0
        children [
          Shape {
            appearance Appearance {
              texture ImageTexture {
                url [
                  "textures/single_door_common.png"
                ]
              }
            }
            geometry DEF DOOR_SHAPE Box {
              size 0.9 2 0.05
            }
          }
        ]
        boundingObject USE DOOR_SHAPE
        physics Physics {
          density -1
          mass 10
        }
      }
    }
  ]
}
DEF SWALL1 Solid {
  translation 0.825 1 0
  children [
    DEF WALL_SHAPE Shape {
      appearance Appearance {
      }
      geometry Box {
        size 1.5 2 0.15
      }
    }
  ]
}
DEF SWALL2 Solid {
  translation 2.325 1 0
  children [
    DEF WALL_SHAPE Shape {
      appearance Appearance {
      }
      geometry Box {
        size 1.5 2 0.15
      }
    }
  ]
}
DEF SWALL3 Solid {
  translation 3.825 1 0
  children [
    DEF WALL_SHAPE Shape {
      appearance Appearance {
      }
      geometry Box {
        size 1.5 2 0.15
      }
    }
  ]
}
DEF SWALL4 Solid {
  translation 5.325 1 0
  children [
    DEF WALL_SHAPE Shape {
      appearance Appearance {
      }
      geometry Box {
        size 1.5 2 0.15
      }
    }
  ]
}
DEF SWALL5 Solid {
  translation 6.825 1 0
  children [
    DEF WALL_SHAPE Shape {
      appearance Appearance {
      }
      geometry Box {
        size 1.5 2 0.15
      }
    }
  ]
}
DEF WWALL1 Solid {
  translation 0 1 -0.825
  rotation 0 1 0 1.5708
  children [
    DEF WALL_SHAPE Shape {
      appearance Appearance {
      }
      geometry Box {
        size 1.5 2 0.15
      }
    }
  ]
}
DEF WWALL2 Solid {
  translation 0 1 -2.325
  rotation 0 1 0 1.5708
  children [
    DEF WALL_SHAPE Shape {
      appearance Appearance {
      }
      geometry Box {
        size 1.5 2 0.15
      }
    }
  ]
}
DEF WWALL3 Solid {
  translation 0 1 -3.825
  rotation 0 1 0 1.5708
  children [
    DEF WALL_SHAPE Shape {
      appearance Appearance {
      }
      geometry Box {
        size 1.5 2 0.15
      }
    }
  ]
}
DEF WWALL4 Solid {
  translation 0 1 -5.325
  rotation 0 1 0 1.5708
  children [
    DEF WALL_SHAPE Shape {
      appearance Appearance {
      }
      geometry Box {
        size 1.5 2 0.15
      }
    }
  ]
}
DEF WWALL5 Solid {
  translation 0 1 -6.825
  rotation 0 1 0 1.5708
  children [
    DEF WALL_SHAPE Shape {
      appearance Appearance {
      }
      geometry Box {
        size 1.5 2 0.15
      }
    }
  ]
}
DEF NWALL1 Solid {
  translation 0.825 1 -7.65
  children [
    DEF WALL_SHAPE Shape {
      appearance Appearance {
      }
      geometry Box {
        size 1.5 2 0.15
      }
    }
  ]
}
DEF NWALL2 Solid {
  translation 2.325 1 -7.65
  children [
    DEF WALL_SHAPE Shape {
      appearance Appearance {
      }
      geometry Box {
        size 1.5 2 0.15
      }
    }
  ]
}
DEF NWALL3 Solid {
  translation 3.825 1 -7.65
  children [
    DEF WALL_SHAPE Shape {
      appearance Appearance {
      }
      geometry Box {
        size 1.5 2 0.15
      }
    }
  ]
}
DEF NWALL4 Solid {
  translation 5.325 1 -7.65
  children [
    DEF WALL_SHAPE Shape {
      appearance Appearance {
      }
      geometry Box {
        size 1.5 2 0.15
      }
    }
  ]
}
DEF NWALL5 Solid {
  translation 6.825 1 -7.65
  children [
    DEF WALL_SHAPE Shape {
      appearance Appearance {
      }
      geometry Box {
        size 1.5 2 0.15
      }
    }
  ]
}
DEF EWALL1 Solid {
  translation 7.575 1 -0.825
  rotation 0 1 0 1.5708
  children [
    DEF WALL_SHAPE Shape {
      appearance Appearance {
      }
      geometry Box {
        size 1.5 2 0.15
      }
    }
  ]
}
DEF EWALL2 Solid {
  translation 7.575 1 -2.325
  rotation 0 1 0 1.5708
  children [
    DEF WALL_SHAPE Shape {
      appearance Appearance {
      }
      geometry Box {
        size 1.5 2 0.15
      }
    }
  ]
}
DEF EWALL3 Solid {
  translation 7.575 1 -3.825
  rotation 0 1 0 1.5708
  children [
    DEF WALL_SHAPE Shape {
      appearance Appearance {
      }
      geometry Box {
        size 1.5 2 0.15
      }
    }
  ]
}
DEF EWALL4 Solid {
  translation 7.575 1 -5.325
  rotation 0 1 0 1.5708
  children [
    DEF WALL_SHAPE Shape {
      appearance Appearance {
      }
      geometry Box {
        size 1.5 2 0.15
      }
    }
  ]
}
DEF EWALL5 Solid {
  translation 7.575 1 -6.825
  rotation 0 1 0 1.5708
  children [
    DEF WALL_SHAPE Shape {
      appearance Appearance {
      }
      geometry Box {
        size 1.5 2 0.15
      }
    }
  ]
}
DEF ROOM1_NWALL Solid {
  translation 2.325 1 -3.075
  children [
    DEF WALL_SHAPE Shape {
      appearance Appearance {
      }
      geometry Box {
        size 1.5 2 0.15
      }
    }
  ]
}
DEF ROOM1_ROOM2_WALL Solid {
  translation 3.075 1 -2.325
  rotation 0 1 0 1.5708
  children [
    DEF WALL_SHAPE Shape {
      appearance Appearance {
      }
      geometry Box {
        size 1.5 2 0.15
      }
    }
  ]
}
DEF ROOM31_WWALL Solid {
  translation 4.575 1 -2.325
  rotation 0 1 0 1.5708
  children [
    DEF WALL_SHAPE Shape {
      appearance Appearance {
      }
      geometry Box {
        size 1.5 2 0.15
      }
    }
  ]
}
DEF ROOM43_EWALL Solid {
  translation 3.075 1 -0.825
  rotation 0 1 0 1.5708
  children [
    DEF WALL_SHAPE Shape {
      appearance Appearance {
      }
      geometry Box {
        size 1.5 2 0.15
      }
    }
  ]
}
DEF ROOM3_SWALL Solid {
  translation 2.325 1 -4.575
  children [
    DEF WALL_SHAPE Shape {
      appearance Appearance {
      }
      geometry Box {
        size 1.5 2 0.15
      }
    }
  ]
}
DEF ROOM3_ROOM4_WALL Solid {
  translation 3.075 1 -5.325
  rotation 0 1 0 1.5708
  children [
    DEF WALL_SHAPE Shape {
      appearance Appearance {
      }
      geometry Box {
        size 1.5 2 0.15
      }
    }
  ]
}
DEF ROOM3_ROOM4_WALL Solid {
  translation 3.07499 1 -6.825
  rotation 0 1 0 1.5708
  children [
    DEF WALL_SHAPE Shape {
      appearance Appearance {
      }
      geometry Box {
        size 1.5 2 0.15
      }
    }
  ]
}
DEF ROOM3_ROOM4_WALL Solid {
  translation 4.58499 1 -6.82501
  rotation 0 1 0 1.5708
  children [
    DEF WALL_SHAPE Shape {
      appearance Appearance {
      }
      geometry Box {
        size 1.5 2 0.15
      }
    }
  ]
}
DEF ROOM1_NWALL Solid {
  translation 6.825 1 -3.075
  children [
    DEF WALL_SHAPE Shape {
      appearance Appearance {
      }
      geometry Box {
        size 1.5 2 0.15
      }
    }
  ]
}
DEF ROOM31_NWALL Solid {
  translation 5.325 1 -3.075
  children [
    DEF WALL_SHAPE Shape {
      appearance Appearance {
      }
      geometry Box {
        size 1.5 2 0.15
      }
    }
  ]
}
DEF ROOM3_SWALL Solid {
  translation 6.825 1 -4.575
  children [
    DEF WALL_SHAPE Shape {
      appearance Appearance {
      }
      geometry Box {
        size 1.5 2 0.15
      }
    }
  ]
}
DEF ROOM3_SWALL Solid {
  translation 5.325 1 -4.575
  children [
    DEF WALL_SHAPE Shape {
      appearance Appearance {
      }
      geometry Box {
        size 1.5 2 0.15
      }
    }
  ]
}
