#VRML_SIM V7.4.3 utf8
WorldInfo {
  info [
    "Description"
    "Author: first name last name <e-mail>"
    "Date: DD MMM YYYY"
  ]
}
Viewpoint {
  orientation 1 1.32183e-19 -3.20291e-19 4.70962
  position 6.27757 18.7572 -3.8222
}
Background {
  skyColor [
    0.4 0.7 1
  ]
}
DirectionalLight {
  ambientIntensity 1
  direction -0.33 -1 -0.5
  castShadows TRUE
}
Supervisor {
  controller "SupervisorController"
}
DEF NAO_BOT Nao {
  translation 0.825 0.334 -6.825
}
Floor {
  size 100 100
}
DEF ROOF RectangleArena {
  translation 0 -1 0
}
DEF R3DOOR Robot {
  translation 1.60378 1.03 -5.81741
  rotation 0 1 0 4.71239
  children [
    Solid {
      translation -0.15 0 0
      children [
        Shape {
          geometry Box {
            size 0.2 2 0.15
          }
        }
      ]
    }
    Solid {
      translation 1.1 0 0
      children [
        Shape {
          geometry Box {
            size 0.3 2 0.15
          }
        }
      ]
    }
    DEF STATIC_BODY Shape {
      appearance Appearance {
        material Material {
          diffuseColor 0.317647 0.317647 0.317647
        }
      }
      geometry Box {
        size 0.05 2.05 0.15
      }
    }
    DEF DOOR HingeJoint {
      jointParameters DEF s18r3 HingeJointParameters {
        axis 0 1 0
        anchor 0.05 0 0
        minStop -2.618
        maxStop 2.618
        staticFriction 0.5
      }
      device PositionSensor {
      }
      endPoint Solid {
        translation 0.44 0 0
        children [
          Shape {
            appearance Appearance {
              texture ImageTexture {
                url [
                  "textures/single_door_common.png"
                ]
              }
            }
            geometry DEF DOOR_SHAPE Box {
              size 0.9 2 0.05
            }
          }
        ]
        boundingObject USE DOOR_SHAPE
        physics Physics {
          density -1
          mass 10
        }
      }
    }
  ]
}
DEF R1DOOR Robot {
  translation 1.81378 1.03 -1.57741
  rotation 0 -1 0 6.28318
  children [
    Solid {
      translation -0.15 0 0
      children [
        Shape {
          geometry Box {
            size 0.2 2 0.15
          }
        }
      ]
    }
    Solid {
      translation 1.1 0 0
      children [
        Shape {
          geometry Box {
            size 0.3 2 0.15
          }
        }
      ]
    }
    DEF STATIC_BODY Shape {
      appearance Appearance {
        material Material {
          diffuseColor 0.317647 0.317647 0.317647
        }
      }
      geometry Box {
        size 0.05 2.05 0.15
      }
    }
    DEF DOOR HingeJoint {
      jointParameters DEF s2r1 HingeJointParameters {
        axis 0 1 0
        anchor 0.05 0 0
        minStop -2.618
        maxStop 2.618
        staticFriction 0.5
      }
      device PositionSensor {
      }
      endPoint Solid {
        translation 0.44 0 0
        children [
          Shape {
            appearance Appearance {
              texture ImageTexture {
                url [
                  "textures/single_door_common.png"
                ]
              }
            }
            geometry DEF DOOR_SHAPE Box {
              size 0.9 2 0.05
            }
          }
        ]
        boundingObject USE DOOR_SHAPE
        physics Physics {
          density -1
          mass 10
        }
      }
    }
  ]
}
DEF R7DOOR Robot {
  translation 6.10378 1.03 -5.79741
  rotation 0 1 0 4.71239
  children [
    Solid {
      translation -0.15 0 0
      children [
        Shape {
          geometry Box {
            size 0.2 2 0.15
          }
        }
      ]
    }
    Solid {
      translation 1.1 0 0
      children [
        Shape {
          geometry Box {
            size 0.3 2 0.15
          }
        }
      ]
    }
    DEF STATIC_BODY Shape {
      appearance Appearance {
        material Material {
          diffuseColor 0.317647 0.317647 0.317647
        }
      }
      geometry Box {
        size 0.05 2.05 0.15
      }
    }
    DEF DOOR HingeJoint {
      jointParameters DEF s19r7 HingeJointParameters {
        axis 0 1 0
        anchor 0.05 0 0
        minStop -2.618
        maxStop 2.618
        staticFriction 0.5
      }
      device PositionSensor {
      }
      endPoint Solid {
        translation 0.44 0 0
        children [
          Shape {
            appearance Appearance {
              texture ImageTexture {
                url [
                  "textures/single_door_common.png"
                ]
              }
            }
            geometry DEF DOOR_SHAPE Box {
              size 0.9 2 0.05
            }
          }
        ]
        boundingObject USE DOOR_SHAPE
        physics Physics {
          density -1
          mass 10
        }
      }
    }
  ]
}
DEF R8DOOR Robot {
  translation 8.86378 1.03 -6.06741
  rotation 0 -1 0 3.14159
  children [
    Solid {
      translation -0.15 0 0
      children [
        Shape {
          geometry Box {
            size 0.2 2 0.15
          }
        }
      ]
    }
    Solid {
      translation 1.1 0 0
      children [
        Shape {
          geometry Box {
            size 0.3 2 0.15
          }
        }
      ]
    }
    DEF STATIC_BODY Shape {
      appearance Appearance {
        material Material {
          diffuseColor 0.317647 0.317647 0.317647
        }
      }
      geometry Box {
        size 0.05 2.05 0.15
      }
    }
    DEF DOOR HingeJoint {
      jointParameters DEF s26r8 HingeJointParameters {
        axis 0 1 0
        anchor 0.05 0 0
        minStop -2.618
        maxStop 2.618
        staticFriction 0.5
      }
      device PositionSensor {
      }
      endPoint Solid {
        translation 0.44 0 0
        children [
          Shape {
            appearance Appearance {
              texture ImageTexture {
                url [
                  "textures/single_door_common.png"
                ]
              }
            }
            geometry DEF DOOR_SHAPE Box {
              size 0.9 2 0.05
            }
          }
        ]
        boundingObject USE DOOR_SHAPE
        physics Physics {
          density -1
          mass 10
        }
      }
    }
  ]
}
DEF R5DOOR Robot {
  translation 6.10378 1.03 -2.79741
  rotation 0 1 0 4.71239
  children [
    Solid {
      translation -0.15 0 0
      children [
        Shape {
          geometry Box {
            size 0.2 2 0.15
          }
        }
      ]
    }
    Solid {
      translation 1.1 0 0
      children [
        Shape {
          geometry Box {
            size 0.3 2 0.15
          }
        }
      ]
    }
    DEF STATIC_BODY Shape {
      appearance Appearance {
        material Material {
          diffuseColor 0.317647 0.317647 0.317647
        }
      }
      geometry Box {
        size 0.05 2.05 0.15
      }
    }
    DEF DOOR HingeJoint {
      jointParameters DEF s9r7 HingeJointParameters {
        axis 0 1 0
        anchor 0.05 0 0
        minStop -2.618
        maxStop 2.618
        staticFriction 0.5
      }
      device PositionSensor {
      }
      endPoint Solid {
        translation 0.44 0 0
        children [
          Shape {
            appearance Appearance {
              texture ImageTexture {
                url [
                  "textures/single_door_common.png"
                ]
              }
            }
            geometry DEF DOOR_SHAPE Box {
              size 0.9 2 0.05
            }
          }
        ]
        boundingObject USE DOOR_SHAPE
        physics Physics {
          density -1
          mass 10
        }
      }
    }
  ]
}
DEF R2DOOR Robot {
  translation 4.58379 1.03 -1.80741
  rotation 0 1 0 1.5708
  children [
    Solid {
      translation -0.15 0 0
      children [
        Shape {
          geometry Box {
            size 0.2 2 0.15
          }
        }
      ]
    }
    Solid {
      translation 1.1 0 0
      children [
        Shape {
          geometry Box {
            size 0.3 2 0.15
          }
        }
      ]
    }
    DEF STATIC_BODY Shape {
      appearance Appearance {
        material Material {
          diffuseColor 0.317647 0.317647 0.317647
        }
      }
      geometry Box {
        size 0.05 2.05 0.15
      }
    }
    DEF DOOR HingeJoint {
      jointParameters DEF s9r2 HingeJointParameters {
        axis 0 1 0
        anchor 0.05 0 0
        minStop -2.618
        maxStop 2.618
        staticFriction 0.5
      }
      device PositionSensor {
      }
      endPoint Solid {
        translation 0.44 0 0
        children [
          Shape {
            appearance Appearance {
              texture ImageTexture {
                url [
                  "textures/single_door_common.png"
                ]
              }
            }
            geometry DEF DOOR_SHAPE Box {
              size 0.9 2 0.05
            }
          }
        ]
        boundingObject USE DOOR_SHAPE
        physics Physics {
          density -1
          mass 10
        }
      }
    }
  ]
}
DEF R4DOOR Robot {
  translation 4.58378 1.03 -4.81741
  rotation 0 1 0 1.5708
  children [
    Solid {
      translation -0.15 0 0
      children [
        Shape {
          geometry Box {
            size 0.2 2 0.15
          }
        }
      ]
    }
    Solid {
      translation 1.1 0 0
      children [
        Shape {
          geometry Box {
            size 0.3 2 0.15
          }
        }
      ]
    }
    DEF STATIC_BODY Shape {
      appearance Appearance {
        material Material {
          diffuseColor 0.317647 0.317647 0.317647
        }
      }
      geometry Box {
        size 0.05 2.05 0.15
      }
    }
    DEF DOOR HingeJoint {
      jointParameters DEF s19r4 HingeJointParameters {
        axis 0 1 0
        anchor 0.05 0 0
        minStop -2.618
        maxStop 2.618
        staticFriction 0.5
      }
      device PositionSensor {
      }
      endPoint Solid {
        translation 0.44 0 0
        children [
          Shape {
            appearance Appearance {
              texture ImageTexture {
                url [
                  "textures/single_door_common.png"
                ]
              }
            }
            geometry DEF DOOR_SHAPE Box {
              size 0.9 2 0.05
            }
          }
        ]
        boundingObject USE DOOR_SHAPE
        physics Physics {
          density -1
          mass 10
        }
      }
    }
  ]
}
DEF R6DOOR Robot {
  translation 9.03379 1.03 -1.81743
  rotation 0 1 0 1.5708
  children [
    Solid {
      translation -0.15 0 0
      children [
        Shape {
          geometry Box {
            size 0.2 2 0.15
          }
        }
      ]
    }
    Solid {
      translation 1.1 0 0
      children [
        Shape {
          geometry Box {
            size 0.3 2 0.15
          }
        }
      ]
    }
    DEF STATIC_BODY Shape {
      appearance Appearance {
        material Material {
          diffuseColor 0.317647 0.317647 0.317647
        }
      }
      geometry Box {
        size 0.05 2.05 0.15
      }
    }
    DEF DOOR HingeJoint {
      jointParameters DEF s10r6 HingeJointParameters {
        axis 0 1 0
        anchor 0.05 0 0
        minStop -2.618
        maxStop 2.618
        staticFriction 0.5
      }
      device PositionSensor {
      }
      endPoint Solid {
        translation 0.44 0 0
        children [
          Shape {
            appearance Appearance {
              texture ImageTexture {
                url [
                  "textures/single_door_common.png"
                ]
              }
            }
            geometry DEF DOOR_SHAPE Box {
              size 0.9 2 0.05
            }
          }
        ]
        boundingObject USE DOOR_SHAPE
        physics Physics {
          density -1
          mass 10
        }
      }
    }
  ]
}
DEF SWALL1 Solid {
  translation 0.825 1 0
  children [
    DEF WALL_SHAPE Shape {
      appearance Appearance {
      }
      geometry Box {
        size 1.5 2 0.15
      }
    }
  ]
}
DEF SWALL2 Solid {
  translation 2.325 1 0
  children [
    DEF WALL_SHAPE Shape {
      appearance Appearance {
      }
      geometry Box {
        size 1.5 2 0.15
      }
    }
  ]
}
DEF SWALL3 Solid {
  translation 3.825 1 0
  children [
    DEF WALL_SHAPE Shape {
      appearance Appearance {
      }
      geometry Box {
        size 1.5 2 0.15
      }
    }
  ]
}
DEF SWALL4 Solid {
  translation 5.325 1 0
  children [
    DEF WALL_SHAPE Shape {
      appearance Appearance {
      }
      geometry Box {
        size 1.5 2 0.15
      }
    }
  ]
}
DEF SWALL5 Solid {
  translation 6.825 1 0
  children [
    DEF WALL_SHAPE Shape {
      appearance Appearance {
      }
      geometry Box {
        size 1.5 2 0.15
      }
    }
  ]
}
DEF SWALL6 Solid {
  translation 8.325 1 0
  children [
    DEF WALL_SHAPE Shape {
      appearance Appearance {
      }
      geometry Box {
        size 1.5 2 0.15
      }
    }
  ]
}
DEF SWALL7 Solid {
  translation 9.825 1 0
  children [
    DEF WALL_SHAPE Shape {
      appearance Appearance {
      }
      geometry Box {
        size 1.5 2 0.15
      }
    }
  ]
}
DEF WWALL1 Solid {
  translation 0 1 -0.825
  rotation 0 1 0 1.5708
  children [
    DEF WALL_SHAPE Shape {
      appearance Appearance {
      }
      geometry Box {
        size 1.5 2 0.15
      }
    }
  ]
}
DEF WWALL2 Solid {
  translation 0 1 -2.325
  rotation 0 1 0 1.5708
  children [
    DEF WALL_SHAPE Shape {
      appearance Appearance {
      }
      geometry Box {
        size 1.5 2 0.15
      }
    }
  ]
}
DEF WWALL3 Solid {
  translation 0 1 -3.825
  rotation 0 1 0 1.5708
  children [
    DEF WALL_SHAPE Shape {
      appearance Appearance {
      }
      geometry Box {
        size 1.5 2 0.15
      }
    }
  ]
}
DEF WWALL4 Solid {
  translation 0 1 -5.325
  rotation 0 1 0 1.5708
  children [
    DEF WALL_SHAPE Shape {
      appearance Appearance {
      }
      geometry Box {
        size 1.5 2 0.15
      }
    }
  ]
}
DEF WWALL5 Solid {
  translation 0 1 -6.825
  rotation 0 1 0 1.5708
  children [
    DEF WALL_SHAPE Shape {
      appearance Appearance {
      }
      geometry Box {
        size 1.5 2 0.15
      }
    }
  ]
}
DEF NWALL1 Solid {
  translation 0.825 1 -7.65
  children [
    DEF WALL_SHAPE Shape {
      appearance Appearance {
      }
      geometry Box {
        size 1.5 2 0.15
      }
    }
  ]
}
DEF NWALL2 Solid {
  translation 2.325 1 -7.65
  children [
    DEF WALL_SHAPE Shape {
      appearance Appearance {
      }
      geometry Box {
        size 1.5 2 0.15
      }
    }
  ]
}
DEF NWALL3 Solid {
  translation 3.825 1 -7.65
  children [
    DEF WALL_SHAPE Shape {
      appearance Appearance {
      }
      geometry Box {
        size 1.5 2 0.15
      }
    }
  ]
}
DEF NWALL4 Solid {
  translation 5.325 1 -7.65
  children [
    DEF WALL_SHAPE Shape {
      appearance Appearance {
      }
      geometry Box {
        size 1.5 2 0.15
      }
    }
  ]
}
DEF NWALL5 Solid {
  translation 6.825 1 -7.65
  children [
    DEF WALL_SHAPE Shape {
      appearance Appearance {
      }
      geometry Box {
        size 1.5 2 0.15
      }
    }
  ]
}
DEF NWALL6 Solid {
  translation 8.325 1 -7.65
  children [
    DEF WALL_SHAPE Shape {
      appearance Appearance {
      }
      geometry Box {
        size 1.5 2 0.15
      }
    }
  ]
}
DEF NWALL7 Solid {
  translation 9.825 1 -7.65
  children [
    DEF WALL_SHAPE Shape {
      appearance Appearance {
      }
      geometry Box {
        size 1.5 2 0.15
      }
    }
  ]
}
DEF EWALL1 Solid {
  translation 10.65 1 -0.825
  rotation 0 1 0 1.5708
  children [
    DEF WALL_SHAPE Shape {
      appearance Appearance {
      }
      geometry Box {
        size 1.5 2 0.15
      }
    }
  ]
}
DEF EWALL2 Solid {
  translation 10.65 1 -2.325
  rotation 0 1 0 1.5708
  children [
    DEF WALL_SHAPE Shape {
      appearance Appearance {
      }
      geometry Box {
        size 1.5 2 0.15
      }
    }
  ]
}
DEF EWALL3 Solid {
  translation 10.65 1 -3.825
  rotation 0 1 0 1.5708
  children [
    DEF WALL_SHAPE Shape {
      appearance Appearance {
      }
      geometry Box {
        size 1.5 2 0.15
      }
    }
  ]
}
DEF EWALL4 Solid {
  translation 10.65 1 -5.325
  rotation 0 1 0 1.5708
  children [
    DEF WALL_SHAPE Shape {
      appearance Appearance {
      }
      geometry Box {
        size 1.5 2 0.15
      }
    }
  ]
}
DEF EWALL5 Solid {
  translation 10.65 1 -6.825
  rotation 0 1 0 1.5708
  children [
    DEF WALL_SHAPE Shape {
      appearance Appearance {
      }
      geometry Box {
        size 1.5 2 0.15
      }
    }
  ]
}
DEF ROOM1_WWALL Solid {
  translation 1.575 1 -2.325
  rotation 0 1 0 1.5708
  children [
    DEF WALL_SHAPE Shape {
      appearance Appearance {
      }
      geometry Box {
        size 1.5 2 0.15
      }
    }
  ]
}
DEF ROOM1_NWALL Solid {
  translation 2.325 1 -3.075
  children [
    DEF WALL_SHAPE Shape {
      appearance Appearance {
      }
      geometry Box {
        size 1.5 2 0.15
      }
    }
  ]
}
DEF ROOM1_ROOM2_WALL Solid {
  translation 3.075 1 -2.325
  rotation 0 1 0 1.5708
  children [
    DEF WALL_SHAPE Shape {
      appearance Appearance {
      }
      geometry Box {
        size 1.5 2 0.15
      }
    }
  ]
}
DEF ROOM2_SWALL Solid {
  translation 3.825 1 -1.575
  children [
    DEF WALL_SHAPE Shape {
      appearance Appearance {
      }
      geometry Box {
        size 1.5 2 0.15
      }
    }
  ]
}
DEF ROOM2_NWALL Solid {
  translation 3.825 1 -3.075
  children [
    DEF WALL_SHAPE Shape {
      appearance Appearance {
      }
      geometry Box {
        size 1.5 2 0.15
      }
    }
  ]
}
DEF MIDWALL1 Solid {
  translation 3.075 1 -3.825
  rotation 0 1 0 1.5708
  children [
    DEF WALL_SHAPE Shape {
      appearance Appearance {
      }
      geometry Box {
        size 1.5 2 0.15
      }
    }
  ]
}
DEF ROOM3_SWALL Solid {
  translation 2.325 1 -4.575
  children [
    DEF WALL_SHAPE Shape {
      appearance Appearance {
      }
      geometry Box {
        size 1.5 2 0.15
      }
    }
  ]
}
DEF ROOM3_NWALL Solid {
  translation 2.325 1 -6.075
  children [
    DEF WALL_SHAPE Shape {
      appearance Appearance {
      }
      geometry Box {
        size 1.5 2 0.15
      }
    }
  ]
}
DEF ROOM3_ROOM4_WALL Solid {
  translation 3.075 1 -5.325
  rotation 0 1 0 1.5708
  children [
    DEF WALL_SHAPE Shape {
      appearance Appearance {
      }
      geometry Box {
        size 1.5 2 0.15
      }
    }
  ]
}
DEF ROOM2_SWALL Solid {
  translation 3.825 1 -4.575
  children [
    DEF WALL_SHAPE Shape {
      appearance Appearance {
      }
      geometry Box {
        size 1.5 2 0.15
      }
    }
  ]
}
DEF ROOM2_NWALL Solid {
  translation 3.825 1 -6.075
  children [
    DEF WALL_SHAPE Shape {
      appearance Appearance {
      }
      geometry Box {
        size 1.5 2 0.15
      }
    }
  ]
}
DEF ROOM1_SWALL Solid {
  translation 6.825 1 -1.575
  children [
    DEF WALL_SHAPE Shape {
      appearance Appearance {
      }
      geometry Box {
        size 1.5 2 0.15
      }
    }
  ]
}
DEF ROOM1_NWALL Solid {
  translation 6.825 1 -3.075
  children [
    DEF WALL_SHAPE Shape {
      appearance Appearance {
      }
      geometry Box {
        size 1.5 2 0.15
      }
    }
  ]
}
DEF ROOM1_ROOM2_WALL Solid {
  translation 7.575 1 -2.325
  rotation 0 1 0 1.5708
  children [
    DEF WALL_SHAPE Shape {
      appearance Appearance {
      }
      geometry Box {
        size 1.5 2 0.15
      }
    }
  ]
}
DEF ROOM2_SWALL Solid {
  translation 8.325 1 -1.575
  children [
    DEF WALL_SHAPE Shape {
      appearance Appearance {
      }
      geometry Box {
        size 1.5 2 0.15
      }
    }
  ]
}
DEF ROOM2_NWALL Solid {
  translation 8.325 1 -3.075
  children [
    DEF WALL_SHAPE Shape {
      appearance Appearance {
      }
      geometry Box {
        size 1.5 2 0.15
      }
    }
  ]
}
DEF MIDWALL1 Solid {
  translation 7.575 1 -3.825
  rotation 0 1 0 1.5708
  children [
    DEF WALL_SHAPE Shape {
      appearance Appearance {
      }
      geometry Box {
        size 1.5 2 0.15
      }
    }
  ]
}
DEF ROOM3_SWALL Solid {
  translation 6.825 1 -4.575
  children [
    DEF WALL_SHAPE Shape {
      appearance Appearance {
      }
      geometry Box {
        size 1.5 2 0.15
      }
    }
  ]
}
DEF ROOM3_NWALL Solid {
  translation 6.825 1 -6.075
  children [
    DEF WALL_SHAPE Shape {
      appearance Appearance {
      }
      geometry Box {
        size 1.5 2 0.15
      }
    }
  ]
}
DEF ROOM3_ROOM4_WALL Solid {
  translation 7.575 1 -5.325
  rotation 0 1 0 1.5708
  children [
    DEF WALL_SHAPE Shape {
      appearance Appearance {
      }
      geometry Box {
        size 1.5 2 0.15
      }
    }
  ]
}
DEF ROOM2_EWALL Solid {
  translation 9.075 1 -5.325
  rotation 0 1 0 1.5708
  children [
    DEF WALL_SHAPE Shape {
      appearance Appearance {
      }
      geometry Box {
        size 1.5 2 0.15
      }
    }
  ]
}
DEF ROOM2_SWALL Solid {
  translation 8.325 1 -4.575
  children [
    DEF WALL_SHAPE Shape {
      appearance Appearance {
      }
      geometry Box {
        size 1.5 2 0.15
      }
    }
  ]
}
